Workbook

Sheet قاعدة بيانات مقدمي الدعم 
A1: قاعدة بيانات مقدمي الدعم للوحدات - ببرنامج وصول
A2: وحدات منفلوط
A3: م | B3: المحافظة | C3: المركز | D3: المكتب | E3: الجمعية / القرية | F3: المشرف الفني | G3: منسق التأهيل | H3: المدير الفني | I3: الأخصائيين | J3: التخصص
A4: 1 | B4: أسيوط | C4: منفلوط | D4: منفلوط | E4: جمعية المحافظة على القرأن الكريم / قرية جحدم | F4: أ/ منى صلاح | G4: أ/ سناء خليفة | H4: أ/ هدى أبو اليزيد
A7: 2 | B7: أسيوط | C7: القوصية | D7: منفلوط | E7: جمعية تنمية المجتمع / تناغه نزالى جانوب | F7: أ/ أسماء حمدي
A10: 3 | B10: أسيوط | C10: القوصية | D10: منفلوط | E10: جمعية دار الهداية بعرب الجهمة | F10: أ/ شيماء أحمد
A13: 4 | B13: أسيوط | C13: القوصية | D13: منفلوط | E13: كيان إنسان بالقوصية | F13: أ/ أسماء حمدي
A16: 5 | B16: أسيوط | C16: القوصية | D16: منفلوط | E16: كيان إنسان بالقصير | F16: أ/ شيماء أحمد
A19: 6 | B19: أسيوط | C19: منفلوط | D19: منفلوط | E19: جمعية تنمية المجتمع بالحواتكة | F19: أ/ شيماء أحمد
A22: 7 | B22: أسيوط | C22: منفلوط | D22: منفلوط | E22: جمعية تنمية المجتمع ببنى شقير | F22: ا/ أيات عبدالله
A25: 8 | B25: أسيوط | C25: القوصية | D25: منفلوط | E25: الجمعية الخيرية الأسلامية بالتمساحية | F25: ا/ الاء عبد الوهاب
A28: 9 | B28: أسيوط | C28: القوصية | D28: منفلوط | E28: جمعية إنسان بالقوصية فرع فزارة | F28: ا/ مصطفى صابر
A31: 10 | B31: أسيوط | C31: القوصية | D31: منفلوط | E31: جمعية جبل قسطام برزقة الدير | F31: ا/ مصطفى صابر
A34: 11 | B34: أسيوط | C34: ديروط | D34: منفلوط | E34: جمعية تنمية المجتمع بنزلة ضاهر | F34: أ/ أسماء حمدي
A37: 12 | B37: أسيوط | C37: ديروط | D37: منفلوط | E37: جمعية تنمية المجتمع بالحوطا الغربية | F37: أ/ صفاء حامد
A40: 13 | B40: أسيوط | C40: ديروط | D40: منفلوط | E40: جمعية كفالة اليتيم وتنمية المجتمع بدشلوط | F40: أ/ نجلاء مصطفى
... A46: 15 | B46: أسيوط | C46: ديروط | D46: منفلوط | E46: جمعية رواد الخير بزاوية هارون | F46: أ/ شيماء أحمد
A49: وحدات أسيوط
A50: 1 | B50: أسيوط | C50: اسيوط | D50: اسيوط | E50: البورة | F50: ا/شيماء خليفة | G50: ا/ايات علي | H50: ا/صفية عبدالمنعم
A53: 2 | B53: أسيوط | C53: اسيوط | D53: اسيوط | E53: منقباد | F53: ا/شيماء خليفة
A56: 3 | B56: أسيوط | C56: اسيوط | D56: اسيوط | E56: ريفا | F56: ا/عنان احمد
A59: 4 | B59: أسيوط | C59: الفتح | D59: اسيوط | E59: الواسطي | F59: ا/ هدير احمد
A62: 5 | B62: أسيوط | C62: ابنوب | D62: اسيوط | E62: كوم المنصورة | F62: ا/هدير احمد
A65: 6 | B65: أسيوط | C65: ابوتيج | D65: اسيوط | E65: رسالة | F65: ا/ سارة احمد
A68: وحدات بنى سويف
A69: 1 | B69: بني سويف | C69: اهناسيا | D69: بني سويف | E69: جمعية النهضة -قرية النويرة | F69: ا/الاء العشري | G69: ا/اسراء حسام | H69: دعاء سيد
A72: 2 | B72: بني سويف | C72: ببا | D72: بني سويف | E72: ببا | F72: ا/ جهاد نجيب
A75: 3 | B75: بني سويف | C75: سدس | D75: بني سويف | E75: جمعية بيت المال -جمعية سدس | F75: ا/سارة محمد
A80: 4 | B80: بني سويف | C80: الواسطي | D80: الواسطي | E80: الرياض | F80: ا/سارة محمد | G80: ا/سارة طاهر | H80: ا/دعاء سيد
A83: وحدات سوهاج
A84: 1 | B84: سوهاج | C84: العسيرات | D84: سوهاج | E84: تنمية المجتمع | F84: أ/ فاطمة عبدالعزيز | G84: أ/ محمود فرغلى | H84: أ/ آية محمد صلاح
A87: 2 | B87: سوهاج | C87: المنشاه | D87: سوهاج | E87: جمعية تنمية المجتمع بقرية كوم بدار
A90: 3 | B90: سوهاج | C90: سوهاج | D90: سوهاج | E90: الجوده من اجل التنميه | F90: جنينه أحمد عبدالرحيم
A93: 4 | B93: سوهاج | C93: سوهاج | D93: المنشاه | E93: سوهاج | F93: أ / فاطمة عبد العزيز
A96: 5 | B96: سوهاج | C96: طهطا | D96: طهطا | E96: الرحمه | F96: أ/ اسراء خالد | G96: أ/ لبني محمود | H96: أ/ ايه صلاح

Sheet تقرير مجمع
A3: م | B3: اسم الوحدة | C3: اجمالى عدد الجلسات التأهيلية | D3: اجمالى عدد الزيارات المنزلية
A4: 1 | B4: جحدم | C4: ='تقرير شهر يناير'!G24+'تقرير فبراير 2023'!G24+'تقرير مارس 2023'!G24+'تقرير مجمع مايو 2023'!G24+'تقرير أبريل 2023'!G24+'تقرير مجمع يونيو 2023'!G24+'تقرير مجمع يوليو 2023'!G24 -> 367 | D4: ='تقرير شهر يناير'!G30+'تقرير فبراير 2023'!G30+'تقرير مارس 2023'!G34+'تقرير مجمع مايو 2023'!G34+'تقرير أبريل 2023'!G34+'تقرير مجمع يونيو 2023'!G34+'تقرير مجمع يوليو 2023'!G34 -> 563
A5: 2 | B5: الحواتكة | C5: ='تقرير شهر يناير'!H24+'تقرير فبراير 2023'!H24+'تقرير مارس 2023'!H24+'تقرير مجمع مايو 2023'!H24+'تقرير أبريل 2023'!H24+'تقرير مجمع يونيو 2023'!H24+'تقرير مجمع يوليو 2023'!H24 -> 751 | D5: ='تقرير شهر يناير'!H30+'تقرير فبراير 2023'!H30+'تقرير مارس 2023'!H34+'تقرير مجمع مايو 2023'!H34+'تقرير أبريل 2023'!H34+'تقرير مجمع يونيو 2023'!H34+'تقرير مجمع يوليو 2023'!H34 -> 1032
A6: 3 | B6: بنى شقير | C6: ='تقرير شهر يناير'!I24+'تقرير فبراير 2023'!I24+'تقرير مارس 2023'!I24+'تقرير مجمع مايو 2023'!I24+'تقرير أبريل 2023'!I24+'تقرير مجمع يونيو 2023'!I24+'تقرير مجمع يوليو 2023'!I24 -> 722 | D6: ='تقرير شهر يناير'!I30+'تقرير فبراير 2023'!I30+'تقرير مارس 2023'!I34+'تقرير مجمع مايو 2023'!I34+'تقرير أبريل 2023'!I34+'تقرير مجمع يونيو 2023'!I34+'تقرير مجمع يوليو 2023'!I34 -> 713
A7: 4 | B7: القوصية | C7: ='تقرير شهر يناير'!J24+'تقرير فبراير 2023'!J24+'تقرير مارس 2023'!J24+'تقرير أبريل 2023'!J24+'تقرير مجمع مايو 2023'!J24+'تقرير مجمع يونيو 2023'!J24+'تقرير مجمع يوليو 2023'!J24 -> 516
A8: 5 | B8: التمساحية | C8: ='تقرير شهر يناير'!K24+'تقرير فبراير 2023'!K24+'تقرير مارس 2023'!K24+'تقرير أبريل 2023'!K24+'تقرير مجمع مايو 2023'!K24+'تقرير مجمع يونيو 2023'!K24+'تقرير مجمع يوليو 2023'!K24 -> 324 | D8: ='تقرير شهر يناير'!K30+'تقرير فبراير 2023'!K30+'تقرير مارس 2023'!K34+'تقرير أبريل 2023'!K34+'تقرير مجمع مايو 2023'!K34+'تقرير مجمع يونيو 2023'!K34+'تقرير مجمع يوليو 2023'!K34 -> 584
A9: 6 | B9: عرب الجهمة | C9: ='تقرير شهر يناير'!L24+'تقرير فبراير 2023'!L24+'تقرير مارس 2023'!L24+'تقرير أبريل 2023'!L24+'تقرير مجمع مايو 2023'!L24+'تقرير مجمع يونيو 2023'!L24+'تقرير مجمع يوليو 2023'!L24 -> 659 | D9: ='تقرير شهر يناير'!L30+'تقرير فبراير 2023'!L30+'تقرير مارس 2023'!L34+'تقرير أبريل 2023'!L34+'تقرير مجمع مايو 2023'!L34+'تقرير مجمع يونيو 2023'!L34+'تقرير مجمع يوليو 2023'!L34 -> 643
A10: 7 | B10: الدير | C10: ='تقرير شهر يناير'!M24+'تقرير فبراير 2023'!M24+'تقرير مارس 2023'!M24+'تقرير أبريل 2023'!M24+'تقرير مجمع مايو 2023'!M24+'تقرير مجمع يونيو 2023'!M24+'تقرير مجمع يوليو 2023'!M24 -> 794 | D10: ='تقرير شهر يناير'!M30+'تقرير فبراير 2023'!M30+'تقرير مارس 2023'!M34+'تقرير أبريل 2023'!M34+'تقرير مجمع مايو 2023'!M34+'تقرير مجمع يونيو 2023'!M34+'تقرير مجمع يوليو 2023'!M34 -> 874
A11: 8 | B11: تناغة | C11: ='تقرير شهر يناير'!N24+'تقرير فبراير 2023'!N24+'تقرير مارس 2023'!N24+'تقرير أبريل 2023'!N24+'تقرير مجمع مايو 2023'!N24+'تقرير مجمع يونيو 2023'!N24+'تقرير مجمع يوليو 2023'!N24 -> 835 | D11: ='تقرير شهر يناير'!N30+'تقرير فبراير 2023'!N30+'تقرير مارس 2023'!N34+'تقرير أبريل 2023'!N34+'تقرير مجمع مايو 2023'!N34+'تقرير مجمع يونيو 2023'!N34+'تقرير مجمع يوليو 2023'!N34 -> 1184
A12: 9 | B12: فزارة | C12: ='تقرير شهر يناير'!O24+'تقرير فبراير 2023'!O24+'تقرير مارس 2023'!O24+'تقرير أبريل 2023'!O24+'تقرير مجمع مايو 2023'!O24+'تقرير مجمع يونيو 2023'!O24+'تقرير مجمع يوليو 2023'!O24 -> 640 | D12: ='تقرير شهر يناير'!O30+'تقرير فبراير 2023'!O24+'تقرير مارس 2023'!O34+'تقرير أبريل 2023'!O34+'تقرير مجمع مايو 2023'!O34+'تقرير مجمع يونيو 2023'!O34+'تقرير مجمع يوليو 2023'!O34 -> 452
A13: 10 | B13: القصير | C13: ='تقرير شهر يناير'!P24+'تقرير فبراير 2023'!P24+'تقرير مارس 2023'!P24+'تقرير أبريل 2023'!P24+'تقرير مجمع مايو 2023'!P24+'تقرير مجمع يونيو 2023'!P24+'تقرير مجمع يوليو 2023'!P24 -> 724 | D13: ='تقرير شهر يناير'!P30+'تقرير فبراير 2023'!P30+'تقرير مارس 2023'!P34+'تقرير أبريل 2023'!P34+'تقرير مجمع مايو 2023'!P34+'تقرير مجمع يونيو 2023'!P34+'تقرير مجمع يوليو 2023'!P34 -> 1210
A14: 11 | B14: نزلة ضاهر | C14: ='تقرير شهر يناير'!Q24+'تقرير فبراير 2023'!Q24+'تقرير مارس 2023'!Q24+'تقرير أبريل 2023'!Q24+'تقرير مجمع مايو 2023'!Q24+'تقرير مجمع يونيو 2023'!Q24+'تقرير مجمع يوليو 2023'!Q24 -> 440 | D14: ='تقرير شهر يناير'!Q30+'تقرير فبراير 2023'!Q30+'تقرير مارس 2023'!Q34+'تقرير أبريل 2023'!Q34+'تقرير مجمع مايو 2023'!Q34+'تقرير مجمع يونيو 2023'!Q34+'تقرير مجمع يوليو 2023'!Q34 -> 726
A15: 12 | B15: ديروط | C15: ='تقرير شهر يناير'!R24+'تقرير فبراير 2023'!R24+'تقرير مارس 2023'!R24+'تقرير أبريل 2023'!R24+'تقرير مجمع مايو 2023'!R24+'تقرير مجمع يونيو 2023'!R24+'تقرير مجمع يوليو 2023'!R24 -> 1004 | D15: ='تقرير شهر يناير'!R30+'تقرير فبراير 2023'!R30+'تقرير مارس 2023'!R34+'تقرير مجمع مايو 2023'!R34+'تقرير أبريل 2023'!R34+'تقرير مجمع يونيو 2023'!R34+'تقرير مجمع يوليو 2023'!R34 -> 20
A16: 13 | B16: الحوطا | C16: ='تقرير شهر يناير'!S24+'تقرير فبراير 2023'!S24+'تقرير مارس 2023'!S24+'تقرير أبريل 2023'!S24+'تقرير مجمع مايو 2023'!S24+'تقرير مجمع يونيو 2023'!S24+'تقرير مجمع يوليو 2023'!S24 -> 716 | D16: ='تقرير شهر يناير'!S30+'تقرير فبراير 2023'!S30+'تقرير مارس 2023'!S34+'تقرير أبريل 2023'!S34+'تقرير مجمع مايو 2023'!S34+'تقرير مجمع يونيو 2023'!S34+'تقرير مجمع يوليو 2023'!S34 -> 609
A17: 14 | B17: دشلوط | C17: ='تقرير شهر يناير'!T24+'تقرير فبراير 2023'!T24+'تقرير مارس 2023'!T24+'تقرير أبريل 2023'!T24+'تقرير مجمع مايو 2023'!T24+'تقرير مجمع يونيو 2023'!T24+'تقرير مجمع يوليو 2023'!T24 -> 542 | D17: ='تقرير شهر يناير'!T30+'تقرير فبراير 2023'!T30+'تقرير مارس 2023'!T34+'تقرير أبريل 2023'!T34+'تقرير مجمع مايو 2023'!T34+'تقرير مجمع يونيو 2023'!T34+'تقرير مجمع يوليو 2023'!T34 -> 678
A18: 15 | B18: زاوية هارون | C18: ='تقرير شهر يناير'!U24+'تقرير فبراير 2023'!U24+'تقرير مارس 2023'!U24+'تقرير مجمع مايو 2023'!U24+'تقرير أبريل 2023'!U24+'تقرير مجمع يونيو 2023'!U24+'تقرير مجمع يوليو 2023'!U24 -> 60 | D18: ='تقرير شهر يناير'!U30+'تقرير فبراير 2023'!U30+'تقرير مارس 2023'!U34+'تقرير مجمع مايو 2023'!U34+'تقرير أبريل 2023'!U34+'تقرير مجمع يونيو 2023'!U34+'تقرير مجمع يوليو 2023'!U34 -> 57
A19: 16 | B19: البورة | C19: ='تقرير مجمع مايو 2023'!V24+'تقرير مجمع يونيو 2023'!V24+'تقرير مجمع يوليو 2023'!V24 -> 229 | D19: ='تقرير مجمع مايو 2023'!V34+'تقرير مجمع يونيو 2023'!V34+'تقرير مجمع يوليو 2023'!V34 -> 270
A20: 17 | B20: منقباد | C20: ='تقرير مجمع مايو 2023'!W24+'تقرير مجمع يونيو 2023'!W24+'تقرير مجمع يوليو 2023'!W24 -> 625 | D20: ='تقرير مجمع مايو 2023'!W34+'تقرير مجمع يونيو 2023'!W34+'تقرير مجمع يوليو 2023'!W34 -> 184
A21: 18 | B21: الواسطى | C21: ='تقرير مجمع مايو 2023'!X24+'تقرير مجمع يونيو 2023'!X24+'تقرير مجمع يوليو 2023'!X24 -> 151 | D21: ='تقرير مجمع مايو 2023'!X34+'تقرير مجمع يونيو 2023'!X34+'تقرير مجمع يوليو 2023'!X34 -> 297
A22: 19 | B22: كوم المنصورة | C22: ='تقرير مجمع مايو 2023'!Y24+'تقرير مجمع يونيو 2023'!Y24+'تقرير مجمع يوليو 2023'!Y24 -> 295 | D22: ='تقرير مجمع مايو 2023'!Y34+'تقرير مجمع يونيو 2023'!Y34+'تقرير مجمع يوليو 2023'!Y34 -> 360
A23: 20 | B23: ريفا | C23: ='تقرير مجمع مايو 2023'!Z24+'تقرير مجمع يونيو 2023'!Z24+'تقرير مجمع يوليو 2023'!Z24 -> 434 | D23: ='تقرير مجمع مايو 2023'!Z34+'تقرير مجمع يونيو 2023'!Z34+'تقرير مجمع يوليو 2023'!Z34 -> 408
A24: 21 | B24: ابوتيج | C24: ='تقرير مجمع مايو 2023'!AA24+'تقرير مجمع يونيو 2023'!AA24+'تقرير مجمع يوليو 2023'!AA24 -> 143 | D24: ='تقرير مجمع مايو 2023'!AA34+'تقرير مجمع يونيو 2023'!AA34+'تقرير مجمع يوليو 2023'!AA34 -> 122
A25: 22 | B25: تونس | C25: ='تقرير فبراير 2023'!V24+'تقرير مارس 2023'!V24+'تقرير أبريل 2023'!V24+'تقرير مجمع مايو 2023'!AB24+'تقرير مجمع يونيو 2023'!AB24+'تقرير مجمع يوليو 2023'!AB24 -> 1041 | D25: ='تقرير فبراير 2023'!V30+'تقرير مارس 2023'!V34+'تقرير أبريل 2023'!V34+'تقرير مجمع مايو 2023'!AB34+'تقرير مجمع يونيو 2023'!AB34+'تقرير مجمع يوليو 2023'!AB34 -> 1080
A26: 23 | B26: المنشأه | C26: ='تقرير مارس 2023'!W24+'تقرير أبريل 2023'!W24+'تقرير مجمع مايو 2023'!AC24+'تقرير مجمع يونيو 2023'!AC24+'تقرير مجمع يوليو 2023'!AC24 -> 423 | D26: ='تقرير مارس 2023'!W34+'تقرير أبريل 2023'!W34+'تقرير مجمع مايو 2023'!AC34+'تقرير مجمع يونيو 2023'!AC34+'تقرير مجمع يوليو 2023'!AC34 -> 780
A27: 24 | B27: العسيرات | C27: ='تقرير مارس 2023'!X24+'تقرير أبريل 2023'!X24+'تقرير مجمع مايو 2023'!AD24+'تقرير مجمع يونيو 2023'!AD24+'تقرير مجمع يوليو 2023'!AD24 -> 563 | D27: ='تقرير مارس 2023'!X34+'تقرير أبريل 2023'!X34+'تقرير مجمع مايو 2023'!AD34+'تقرير مجمع يونيو 2023'!AD34+'تقرير مجمع يوليو 2023'!AD34 -> 573
A28: 25 | B28: كوم بدار | C28: ='تقرير مارس 2023'!Y24+'تقرير أبريل 2023'!Y24+'تقرير مجمع مايو 2023'!AE24+'تقرير مجمع يونيو 2023'!AE24+'تقرير مجمع يوليو 2023'!AE24 -> 616 | D28: ='تقرير مارس 2023'!Y34+'تقرير أبريل 2023'!Y34+'تقرير مجمع مايو 2023'!AE34+'تقرير مجمع يونيو 2023'!AE34+'تقرير مجمع يوليو 2023'!AE34 -> 734
A29: 26 | B29: فزارة / طهطا | C29: ='تقرير مارس 2023'!Z24+'تقرير أبريل 2023'!Z24+'تقرير مجمع مايو 2023'!AF24+'تقرير مجمع يونيو 2023'!AF24+'تقرير مجمع يوليو 2023'!AF24 -> 668 | D29: ='تقرير مارس 2023'!Z34+'تقرير أبريل 2023'!Z34+'تقرير مجمع مايو 2023'!AF34+'تقرير مجمع يونيو 2023'!AF34+'تقرير مجمع يوليو 2023'!AF34 -> 738
A30: 27 | B30: النويرة | C30: ='تقرير أبريل 2023'!AA24+'تقرير مجمع مايو 2023'!AG24+'تقرير مجمع يونيو 2023'!AG24+'تقرير مجمع يوليو 2023'!AG24 -> 585 | D30: ='تقرير أبريل 2023'!AA34+'تقرير مجمع مايو 2023'!AG34+'تقرير مجمع يونيو 2023'!AG34+'تقرير مجمع يوليو 2023'!AG34 -> 335
A31: 28 | B31: ببا | C31: ='تقرير مارس 2023'!AA24+'تقرير أبريل 2023'!AB24+'تقرير مجمع مايو 2023'!AH24+'تقرير مجمع يونيو 2023'!AH24+'تقرير مجمع يوليو 2023'!AH24 -> 966 | D31: ='تقرير مارس 2023'!AA34+'تقرير أبريل 2023'!AB34+'تقرير مجمع مايو 2023'!AH34+'تقرير مجمع يونيو 2023'!AH34+'تقرير مجمع يوليو 2023'!AH34 -> 590
A32: 29 | B32: سدس | C32: ='تقرير مجمع مايو 2023'!AI24+'تقرير مجمع يونيو 2023'!AI24+'تقرير مجمع يوليو 2023'!AI24 -> 215 | D32: ='تقرير مجمع مايو 2023'!AI34+'تقرير مجمع يونيو 2023'!AI34+'تقرير مجمع يوليو 2023'!AI34 -> 295
A33: 30 | B33: الرياض | C33: ='تقرير مجمع مايو 2023'!AJ24+'تقرير مجمع يونيو 2023'!AJ24+'تقرير مجمع يوليو 2023'!AJ24 -> 199 | D33: ='تقرير مجمع مايو 2023'!AJ34+'تقرير مجمع يونيو 2023'!AJ34+'تقرير مجمع يوليو 2023'!AJ34 -> 53
B34: اجمالى | C34: =SUM(C4:C33) -> 16247 | D34: =SUM(D4:D33) -> 16164

Sheet قاعدة بيانات مسئولات التاهيل 
A1: قاعدة بيانات مسئولات التأهيل ببرنامج وصول
A2: الوحدة | B2: م | C2: الاسم | D2: المحافظة | E2: المركز | F2: القرية | G2: المؤهل الدراسي | H2: تاريخ الميلاد | I2: الرقم القومي | J2: سنوات خبرة سابقة في الإعاقة | K2: تاريخ بدء العمل | L2: تاريخ انهاء التعاقد | M2: التدريبات التي حصلت عليها | N2: احتياجات تدريبية
A3: 1- جمعيه المحافظة القران الكريم بجحدم | B3: 1 | C3: فاطمه مصطفى منصور عبد المتجلى | D3: اسيوط | E3: منفلوط | F3: جحدم | G3: بكالوريوس تجاره | H3: 35578 | I3: 29705282500801 | J3: عام | K3: 44896 | L3: 45474
B4: 2 | C4: شيماء احمد محمود راتب | G4: ليسانس تربيه قسم لغه عربيه | H4: 37167 | I4: 30103102504826 | J4: بدون | K4: 44774 | L4: 45474
B5: 3 | C5: ------------ | L5: 45474
A6: 2- جمعية تنمية المجتمع / تناغه نزالى جانوب | B6: 4 | C6: حنان توفيق مجلى سيف | D6: اسيوط | E6: القوصية | F6: تناغه | G6: ليسانس لغة عربية | H6: 27/1/1986 | I6: 28601272500923 | J6: سنتين فى كيان | K6: 44473 | L6: 45474
B7: 5 | C7: غادة محروس أحمد جبر | G7: بكالريوس خدمة إجتماعية | H7: 7/12/1988 | I7: 28812072500903 | J7: سنتين فى كيان | K7: 44473 | L7: 45474
B8: 6 | C8: نورة رمضان عبدالنعيم أحمد | G8: دبلوم تجارة | H8: 25/2/1989 | I8: 289022525000641 | J8: بدون | K8: 44845 | L8: 45474
A9: 3- جمعية كفالة اليتيم وتنمية المجتمع بدشلوط | B9: 7 | C9: سناء حمدى عبد اللاه | D9: اسيوط | E9: ديروط | F9: دشلوط | G9: دبلوم صنايع | H9: 30287 | I9: 28212022500549 | J9: لايوجد | K9: 44866 | L9: 45474 | M9: تكامل حسى / تعديل سلوك / تخاطب / تنمية مهارات / تأهيل حركى / اعاقة بصرية / اعاقة سمعية حماية الطفل / زيارات منزلية | N9: اكاديمى/ شلل دماغى
B10: 8 | C10: حنان ابراهيم زكريا | H10: 35156 | I10: 29604012505525 | J10: لايوجد | K10: 44866 | L10: 45474 | M10: تكامل حسى / تعديل سلوك / تخاطب / تنمية مهارات / تأهيل حركى / اعاقة بصرية / اعاقة سمعية حماية الطفل / زيارات منزلية | N10: اكاديمى/ شلل دماغى
B11: 9 | C11: نعمه حسن عبد الرازق | H11: 32207 | I11: 28803052500461 | J11: لايوجد | K11: 44866 | L11: 45474 | M11: تكامل حسى / تعديل سلوك / تخاطب / تنمية مهارات / تأهيل حركى / اعاقة بصرية / اعاقة سمعية حماية الطفل / زيارات منزلية | N11: اكاديمى/ شلل دماغى
A12: 4-كيان إنسان بالقوصية | B12: 10 | C12: أسماء عبدالحكم فهمى أبو العلا | D12: اسيوط | E12: القوصية | F12: ----- | G12: بكالريوس خدمة إجتماعية/دبلوم علم نفس/دبلوم المعاقين / ماجستير فى الخدمة الإجتماعية | H12: 14/12/1991 | I12: 29112142500908 | J12: سنة ونصف | K12: 44473 | L12: 45474 | M12: تكامل حسى / تعديل سلوك / تخاطب / تنمية مهارات / تأهيل حركى / اعاقة بصرية / اعاقة سمعية حماية الطفل / زيارات منزلية | N12: شلل دماغى
B13: 11 | C13: سمر محمود محمد سليم | H13: 27/6/1989 | I13: 28906272500601 | J13: لايوجد | K13: 44572 | L13: 45474 | M13: تكامل حسى / تعديل سلوك / تخاطب / تنمية مهارات / تأهيل حركى / اعاقة بصرية / اعاقة سمعية حماية الطفل / زيارات منزلية | N13: شلل دماغى
B14: 12
A15: 5- كيان إنسان بالقصير | B15: 13 | C15: ايمان فنجري عبد النظير | D15: اسيوط | E15: القوصية | G15: ثانوية عامة | H15: 30800 | I15: 28404282500867 | J15: 2 عام | K15: 44473 | L15: 45474 | M15: التأهيل المرتكز على المجتمع - المفاهيم الحديثة للإعاقة - العمل مع الاسر -برنامج البورتيدج -ادلة منظمة الصحة العالمية -سلوك الاطفال والمراهقين -سياسة الحماية -الاعاقة البصرية -المهارات اللغوية والسمعية واضطرابات النطق -المشكلات الحسية -التعامل مع الورد والاكسل
B16: 14 | C16: صابرةعوض عبد السلام | G16: ثانوية عامة | H16: 35898 | I16: 29804132501123 | J16: 2 عام | K16: 44473 | L16: 45474 | M16: العمل مع الاسر -برنامج البورتيدج -ادلة منظمة الصحة العالمية -سلوك الاطفال والمراهقين -سياسة الحماية -الاعاقة البصرية -المهارات اللغوية والسمعية واضطرابات النطق -المشكلات الحسية -التعامل مع الورد والاكسل
B17: 15 | C17: دعاء صقر عمر عبدالشافي | G17: ثانوية عامة | H17: 35712 | I17: 29701092500923 | J17: بدون | K17: 44774 | L17: 45474 | M17: العمل مع الاسر -برنامج البورتيدج -ادلة منظمة الصحة العالمية -سلوك الاطفال والمراهقين -سياسة الحماية -الاعاقة البصرية -المهارات اللغوية والسمعية واضطرابات النطق -المشكلات الحسية -التعامل مع الورد والاكسل
A18: 6- عرب الجهمة | B18: 16 | C18: اشجان سمير إبراهيم | D18: اسيوط | E18: القوصية | F18: عرب الجهمة | G18: بكالوريوس خدمة اجتماعية | H18: 22/10/87 | I18: 28710222500845 | J18: 3 سنوات | K18: ديسمبر-٢٢ | L18: 45474 | M18: العمل مع الاسر -برنامج البورتيدج -ادلة منظمة الصحة العالمية -سلوك الاطفال والمراهقين -سياسة الحماية -الاعاقة البصرية -المهارات اللغوية والسمعية واضطرابات النطق -المشكلات الحسية -التعامل مع الورد والاكسل | N18: التاهيل الحركى لاطفال الضمور
B19: 17 | C19: عنود محمود على | G19: ليسانس آداب وثائق ومكتبات | H19: 1/21997 | I19: 29702012504687 | J19: لايوجد | K19: ديسمبر-٢٢ | L19: 45474 | M19: العمل مع الاسر -برنامج البورتيدج -ادلة منظمة الصحة العالمية -سلوك الاطفال والمراهقين -سياسة الحماية -الاعاقة البصرية -المهارات اللغوية والسمعية واضطرابات النطق -المشكلات الحسية -التعامل مع الورد والاكسل | N19: التاهيل الحركى لاطفال الضمور
B20: 18 | C20: آيه احمد صالح | G20: بكالوريوس تربية نوعية | H20: 06/05/96 | I20: 29605062500946 | J20: لايوجد | K20: ديسمبر-٢٢ | L20: 45474 | M20: العمل مع الاسر -برنامج البورتيدج -ادلة منظمة الصحة العالمية -سلوك الاطفال والمراهقين -سياسة الحماية -الاعاقة البصرية -المهارات اللغوية والسمعية واضطرابات النطق -المشكلات الحسية -التعامل مع الورد والاكسل | N20: التاهيل الحركى لاطفال الضمور
A21: 7- وحدة بنى شقير | B21: 19 | C21: نورا عمر محمد شحاتة | D21: اسيوط | E21: منفلوط | F21: بنى شقير | G21: دبلوم تجارة | H21: 34301 | I21: 29311282500749 | J21: 3 سنوات | K21: عام 2019 | L21: 45474 | M21: العمل مع الاسر -برنامج البورتيدج -ادلة منظمة الصحة العالمية -سلوك الاطفال والمراهقين -سياسة الحماية -الاعاقة البصرية -المهارات اللغوية والسمعية واضطرابات النطق -المشكلات الحسية -التعامل مع الورد والاكسل | N21: تدريب عن لغة الاشاره
B22: 20 | C22: هبة عمر محمد شحاته | G22: دبلوم تجارة | H22: 33790 | I22: 29207052501647 | J22: 3 سنوات | K22: عام 2019 | L22: 45474 | M22: العمل مع الاسر -برنامج البورتيدج -ادلة منظمة الصحة العالمية -سلوك الاطفال والمراهقين -سياسة الحماية -الاعاقة البصرية -المهارات اللغوية والسمعية واضطرابات النطق -المشكلات الحسية -التعامل مع الورد والاكسل | N22: تدريب عن لغه الاشاره وكيفيه التعامل معها
B23: 21 | C23: أمل عبدالمالك عثمان | G23: دبلوم تجارة | H23: 29845 | I23: 28109162501108 | J23: لايوجد | K23: 44958 | L23: 45474
A24: 8 -وحدة رزقة الدير | B24: 22 | C24: ايمان يوسف غالي | D24: اسيوط | E24: القوصية | F24: رزقة الدير | G24: كلية آداب | H24: 33710 | I24: 29204162500485 | J24: لايوجد | K24: 44866 | L24: 45474 | M24: تكامل حسى / تعديل سلوك / تخاطب / تنمية مهارات / تأهيل حركى / اعاقة بصرية / اعاقة سمعية حماية الطفل / زيارات منزلية
B25: 23 | C25: حنان عيد رزق | G25: دبلوم صنايع | H25: 32366 | I25: 29604012505525 | J25: لايوجد | K25: 44866 | L25: 45474 | M25: تكامل حسى / تعديل سلوك / تخاطب / تنمية مهارات / تأهيل حركى / اعاقة بصرية / اعاقة سمعية حماية الطفل / زيارات منزلية
B26: 24 | C26: هبه عزت صديق | G26: دبلوم تجارة | H26: 31970 | I26: 28707122500804 | J26: لايوجد | K26: 44866 | L26: 45474 | M26: تكامل حسى / تعديل سلوك / تخاطب / تنمية مهارات / تأهيل حركى / اعاقة بصرية / اعاقة سمعية حماية الطفل / زيارات منزلية
A27: 9- وحدة نزلة ضاهر | B27: 25 | C27: أميرة صالح عبدالحفيظ سيد | D27: أسيوط | E27: ديروط | F27: نزلة ضاهر | G27: ليسانس آداب قسم تاريخ | H27: 33852 | I27: 29209052500325 | J27: 7سنوات أبحاث لذوى الإعاقة | K27: 44774 | L27: 45474 | M27: تدريب برنامج وصول 2 نظرى و عملى | N27: تدريب مهارات حياتيه / الدعم التفسى/ كورس إنجلش
B28: 26 | C28: أميرة عبدالتواب حسن مبروك | G28: دبلوم تجارة | H28: 34283 | I28: 29311102500703 | J28: 7سنوات أبحاث لذوى الإعاقة | K28: 44774 | L28: 45474 | M28: iCDL /تدريب تخاطب / تدريب برنامج وصول نظرى و عملى | N28: كورس إنجلش / كور دكتور فينكس / كورس دكتور ماث
B29: 27 | C29: عهود محمود مهران سيد | G29: بكالريوس تجارة قسم إدارة أعمال | H29: 34661 | I29: 29411232501005 | J29: لا يوجد | K29: 44774 | L29: 45474 | M29: تدريب برنامج وصول 2 نظرى و عملى
A30: 10- كفالة اليتم ديروط | B30: 28 | C30: هاجر محمد سيد محمد | D30: اسيوط | E30: ديروط | F30: مدينة ديروط | G30: ليسانس آداب + دبلوم عام تربوي+ دبلوم مهني معلم تربية خاصة | H30: 33270 | I30: 29102012500544 | J30: سنة | K30: 44774 | L30: 45474 | M30: إرشاد نفسي توحد وتخاطب - تقييم بورتاج الإعاقة السمعية والبصرية - الإعاقة الحركية للشلل الدماغي - المشكلات السلوكية والحسية
B31: 29 | C31: نعمة راشد حسين إبراهيم | G31: ليسانس آداب + دبلوم عام تربوي حاسب ألي | H31: 34839 | I31: 29505202404247 | J31: لا يوجد | K31: 44774 | L31: 45474 | M31: رشاد نفسي توحد وتخاطب - تقييم بورتاج - إعاقة السمعية والبصرية - الإعاقة الحركية للشلل الدماغي - المشكلات السلوكية والحسية
B32: 30 | C32: نجلاء حسني نياظ أحمد | G32: بكالريوس تجارة قسم إدارة اعمال | H32: 31736 | I32: 28611202500727 | J32: لا يوجد | K32: 44774 | L32: 45474 | M32: ارشاد نفسي توحد وتخاطب - تقييم بورتاج - إعاقة السمعية والبصرية -الإعاقة الحركية للشلل الدماغي - المشكلات السلوكية والحسية
A33: 11- وحدة التمساحية | B33: 31 | C33: أميرة عبد الرحيم أحمد رباعي | G33: معهد فني تجاري | H33: 26/11/2000 | I33: 30011262500248 | J33: لا يوجد | K33: 15/10/2023 | L33: 45474 | M33: -برنامج البورتيدج -ادلة منظمة الصحة العالمية -سلوك الاطفال والمراهقين -سياسة الحماية -الاعاقة البصرية -المهارات اللغوية والسمعية واضطرابات النطق -المشكلات الحسية -التعامل مع الورد والاكسل | N33: العمل مع الأسر
B34: 32 | C34: فاطمة محمود حسين عبد المولى | G34: دبلوم تجاري | H34: 20\11\1996 | I34: 29611202501328 | J34: لا يوجد | K34: 23/11/23 | L34: 45474 | M34: برنامج البورتيدج -ادلة منظمة الصحة العالمية -سلوك الاطفال والمراهقين -سياسة الحماية -الاعاقة البصرية -المهارات اللغوية والسمعية واضطرابات النطق -المشكلات الحسية -التعامل مع الورد والاكسل | N34: التأهيل المرتكز على المجتمع
B35: 33 | C35: هند محمود أحمد مطاوع | G35: دبلوم فني تجاري | H35: 33594 | I35: 29112222500861 | J35: لا يوجد | K35: 44958 | L35: 45474 | M35: لم تتلقى سوى حضور جلسات عملية | N35: تحتاج إلى كل التدريبات التي تخص مجال التربية الخاصة
A36: 12- وحدة الحواتكة | B36: 34 | C36: ناديه محمد سيد | D36: اسيوط | E36: منفلوط | F36: الحواتكه | G36: ليسانس حقوق | H36: 31087 | I36: 28502092501605 | K36: 44896 | M36: التأهيل المرتكز على المجتمع - المفاهيم الحديثة للإعاقة - العمل مع الاسر -برنامج البورتيدج -ادلة منظمة الصحة العالمية -سلوك الاطفال والمراهقين -سياسة الحماية -الاعاقة البصرية -المهارات اللغوية والسمعية واضطرابات النطق -المشكلات الحسية -التعامل مع الورد والاكسل | N36: الاحتياج الى التدريب العملى على كل انواع الاعاقات
B37: 35 | C37: نحلاء على عبدالرحيم | G37: دبلوم تجاره | H37: 31234 | I37: 28507062502306 | K37: 44896 | M37: التأهيل المرتكز على المجتمع - المفاهيم الحديثة للإعاقة - العمل مع الاسر -برنامج البورتيدج -ادلة منظمة الصحة العالمية -سلوك الاطفال والمراهقين -سياسة الحماية -الاعاقة البصرية -المهارات اللغوية والسمعية واضطرابات النطق -المشكلات الحسية -التعامل مع الورد والاكسل | N37: الاحتياج الى التدريب العملى على كل انواع الاعاقات
B38: 36 | C38: منى عبدالرحيم عبدالرحمن | G38: دبلوم تجاره | H38: 32168 | I38: 28801262501327 | K38: 44896 | M38: -برنامج البورتيدج -ادلة منظمة الصحة العالمية -سلوك الاطفال والمراهقين -سياسة الحماية -الاعاقة البصرية -المهارات اللغوية والسمعية واضطرابات النطق -المشكلات الحسية -التعامل مع الورد والاكسل | N38: الاحتياج الى التدريب العملى على كل انواع الاعاقات
A39: 13- وحدة فزارة | B39: 37 | C39: سعاد هارون محمد | D39: اسيوط | E39: القوصية | F39: فزارة | G39: معهدفنى شعبةكمبيوتر | H39: 29503 | I39: 28010092500463 | J39: لايوجد | K39: 44866 | L39: 45474 | M39: العمل مع الاسر -برنامج البورتيدج -ادلة منظمة الصحة العالمية -سلوك الاطفال والمراهقين -سياسة الحماية -الاعاقة البصرية -المهارات اللغوية والسمعية واضطرابات النطق -المشكلات الحسية -التعامل مع الورد والاكسل
B40: 38 | C40: ياسمين احمد عبدالكريم | G40: دبلوم تجاره | H40: 35973 | I40: 29806272500685 | J40: لايوجد | K40: 44866 | L40: 45474 | M40: العمل مع الاسر -برنامج البورتيدج -ادلة منظمة الصحة العالمية -سلوك الاطفال والمراهقين -سياسة الحماية -الاعاقة البصرية -المهارات اللغوية والسمعية واضطرابات النطق -المشكلات الحسية -التعامل مع الورد والاكسل
...

Sheet تقرير شهر يناير
C1: وحدات مكتب منفلوط | W1: وحات مكتب أسيوط
G2: جحدم | H2: الحواتكة | I2: بنى شقير | J2: القوصية | K2: التمساحية | L2: عرب الجهمة | M2: الدير | N2: تناغة | O2: فزارة | P2: القصير | Q2: نزلة ضاهر | R2: ديروط | S2: الحوطا الغربية | T2: دشلوط | U2: زاوية هارون | V2: إجمالى | W2: الواسطى | X2: كوم المنصورة | Y2: أبو تيج | Z2: منقباد | AA2: البورة | AB2: ريفا
A3: إجمالي المستفيدين | B3: إجمالي المستفيدين بالوحدة خلال العام | G3: 120 | H3: 120 | I3: 120 | J3: 120 | K3: 120 | L3: 120 | M3: 120 | N3: 120 | O3: 120 | P3: 120 | Q3: 120 | R3: 120 | S3: 120 | T3: 120 | U3: 120 | V3: =SUM(U3+T3+S3+R3+Q3+P3+O3+N3+M3+L3+K3+J3+I3+H3+G3) -> 1800
B4: إجمالي المستفيدين بالوحدة شهريًا | G4: 80 | H4: 120 | I4: 81 | J4: 80 | K4: 80 | L4: 15 | M4: 120 | N4: 90 | O4: 120 | P4: 120 | Q4: 120 | R4: 120 | S4: 120 | T4: 120 | U4: 0 | V4: =SUM(U4+T4+S4+R4+Q4+P4+O4+N4+M4+L4+K4+J4+I4+H4+G4) -> 1386
A5: عدد الأطفال ذوى الإعاقة (الجلسات التأهيلية داخل بالبرنامج ) | B5: المخطط خلال العام | G5: 20 | H5: 30 | I5: 20 | J5: 20 | K5: 0 | L5: 30 | M5: 30 | N5: 30 | O5: 30 | P5: 30 | Q5: 30 | R5: 60 | S5: 30 | T5: 30 | U5: 0 | V5: =SUM(U5+T5+S5+R5+Q5+P5+O5+N5+M5+L5+K5+J5+I5+H5+G5) -> 390
B6: عدد الأطفال الجدد الذين تم إضافتهم خلال الشهر | G6: 20 | H6: 21 | I6: 21 | J6: 6 | K6: 0 | L6: 11 | M6: 16 | N6: 10 | O6: 9 | P6: 14 | Q6: 11 | R6: 7 | S6: 15 | T6: 30 | U6: 0 | V6: =SUM(U6+T6+S6+R6+Q6+P6+O6+N6+M6+L6+K6+J6+I6+H6+G6) -> 191
B7: عدد الأطفال المنقطعين عن الخدمة خلال الشهر | G7: 0 | H7: 0 | I7: 0 | J7: 3 | K7: 0 | L7: 0 | M7: 0 | N7: 0 | O7: 0 | P7: 0 | Q7: 0 | R7: 0 | S7: 0 | T7: 0 | U7: 0 | V7: =SUM(U7+T7+S7+R7+Q7+P7+O7+N7+M7+L7+K7+J7+I7+H7+G7) -> 3
B8: عدد المستفيدين شهريا من الأطفال (ذكور ) | G8: 11 | I8: 9 | J8: 6 | K8: 0 | L8: 7 | M8: 12 | N8: 22 | O8: 6 | P8: 20 | Q8: 2 | R8: 3 | S8: 12 | T8: 21 | U8: 0 | V8: =SUM(U8+T8+S8+R8+Q8+P8+O8+N8+M8+L8+K8+J8+I8+H8+G8) -> 131
B9: عدد المستفيدين شهريا من الأطفال (اناث) | G9: 9 | I9: 11 | J9: 2 | K9: 0 | L9: 4 | M9: 4 | N9: 8 | O9: 3 | P9: 10 | Q9: 9 | R9: 4 | S9: 3 | T9: 16 | U9: 0 | V9: =SUM(U9+T9+S9+R9+Q9+P9+O9+N9+M9+L9+K9+J9+I9+H9+G9) -> 83
B10: إجمالي عدد الأطفال المنتظمين بالوحدة خلال الشهر (تحت 14 عام ) | G10: 20 | H10: 21 | I10: 21 | J10: 8 | K10: 0 | M10: 16 | N10: 30 | O10: 9 | P10: 30 | Q10: 11 | R10: 7 | S10: 15 | T10: 30 | U10: 0 | V10: =SUM(U10+T10+S10+R10+Q10+P10+O10+N10+M10+L10+K10+J10+I10+H10+G10) -> 218
A11: عدد الأشخاص/الأطفال ذوى الإعاقة (الزيارات المنزلية ) | B11: المخطط خلال العام | G11: 90 | H11: 90 | I11: 90 | J11: 60 | K11: 0 | L11: 90 | M11: 90 | N11: 90 | O11: 90 | P11: 90 | Q11: 90 | R11: 0 | S11: 90 | T11: 90 | U11: 0 | V11: =SUM(U11+T11+S11+R11+Q11+P11+O11+N11+M11+L11+K11+J11+I11+H11+G11) -> 1050
B12: عدد الأشخاص/الأطفال الجدد الذين تم إضافتهم خلال الشهر | G12: 60 | H12: 0 | I12: 63 | J12: 0 | K12: 0 | L12: 0 | M12: 30 | N12: 60 | O12: 0 | P12: 90 | Q12: 5 | R12: 0 | S12: 15 | T12: 92 | U12: 0 | V12: =SUM(U12+T12+S12+R12+Q12+P12+O12+N12+M12+L12+K12+J12+I12+H12+G12) -> 415 | W12: 415
B13: عدد الأطفال المنقطعين عن الخدمة خلال الشهر | G13: 0 | H13: 0 | I13: 0 | J13: 0 | K13: 0 | L13: 0 | M13: 0 | N13: 0 | O13: 0 | P13: 0 | Q13: 0 | R13: 0 | S13: 0 | T13: 0 | U13: 0 | V13: =SUM(U13+T13+S13+R13+Q13+P13+O13+N13+M13+L13+K13+J13+I13+H13+G13) -> 0 | W13: 0
B14: عدد المستفيدين شهريا من الأطفال (ذكور ) | G14: 8 | I14: 20 | J14: 0 | K14: 0 | L14: 0 | M14: 6 | N14: 11 | O14: 0 | P14: 8 | Q14: 4 | R14: 0 | S14: 3 | T14: 22 | U14: 0 | V14: =SUM(U14+T14+S14+R14+Q14+P14+O14+N14+M14+L14+K14+J14+I14+H14+G14) -> 82
B15: عدد المستفيدين شهريا من الأطفال (اناث) | G15: 8 | I15: 14 | J15: 0 | K15: 0 | L15: 0 | M15: 4 | N15: 8 | O15: 0 | P15: 7 | Q15: 0 | R15: 0 | S15: 4 | T15: 16 | U15: 0 | V15: =SUM(U15+T15+S15+R15+Q15+P15+O15+N15+M15+L15+K15+J15+I15+H15+G15) -> 61
B16: عدد المستفيدين شهريا من البالغين (ذكور ) | G16: 23 | I16: 15 | J16: 0 | K16: 0 | L16: 0 | M16: 35 | N16: 21 | O16: 0 | P16: 35 | Q16: 0 | R16: 0 | S16: 5 | T16: 19 | U16: 0 | V16: =SUM(U16+T16+S16+R16+Q16+P16+O16+N16+M16+L16+K16+J16+I16+H16+G16) -> 153
B17: عدد المستفيدين شهريا من البالغين (اناث) | G17: 21 | I17: 12 | J17: 0 | K17: 0 | L17: 0 | M17: 45 | N17: 21 | O17: 0 | P17: 40 | Q17: 1 | R17: 0 | S17: 3 | T17: 35 | U17: 0 | V17: =SUM(U17+T17+S17+R17+Q17+P17+O17+N17+M17+L17+K17+J17+I17+H17+G17) -> 178
B18: إجمالي عدد المستفيدين من خدمة الزيارات المنزلية شهريًا | G18: 60 | I18: 63 | J18: 0 | K18: 0 | L18: 0 | M18: 90 | N18: 60 | O18: 0 | P18: 90 | Q18: 5 | R18: 0 | S18: 15 | T18: 92 | U18: 0 | V18: =SUM(U18+T18+S18+R18+Q18+P18+O18+N18+M18+L18+K18+J18+I18+H18+G18) -> 475
A19: الجلسات التأهيلية داخل الوحدة | B19: جلسات إرشاد للأشخاص أنفسهم | C19: المستهدف الشهري | K19: 0 | U19: 0 | V19: =SUM(U19+T19+S19+R19+Q19+P19+O19+N19+M19+L19+K19+J19+I19+H19+G19) -> 0
C20: الفعلي شهريًا | K20: 0 | U20: 0 | V20: =SUM(U20+T20+S20+R20+Q20+P20+O20+N20+M20+L20+K20+J20+I20+H20+G20) -> 0
B21: جلسات إرشاد لأسر أ.ذ.إ | C21: المستهدف الشهري | K21: 0 | U21: 0 | V21: =SUM(U21+T21+S21+R21+Q21+P21+O21+N21+M21+L21+K21+J21+I21+H21+G21) -> 0
C22: الفعلي شهريًا | K22: 0 | U22: 0 | V22: =SUM(U22+T22+S22+R22+Q22+P22+O22+N22+M22+L22+K22+J22+I22+H22+G22) -> 0
B23: جلسات تأهيلية للأطفال | C23: المستهدف الشهري | I23: 90 | J23: 90 | K23: 0 | P23: 140 | S23: 140 | U23: 0 | V23: =SUM(U23+T23+S23+R23+Q23+P23+O23+N23+M23+L23+K23+J23+I23+H23+G23) -> 460
C24: الفعلي شهريًا | I24: 98 | J24: 40 | K24: 0 | P24: 75 | S24: 80 | U24: 0 | V24: =SUM(U24+T24+S24+R24+Q24+P24+O24+N24+M24+L24+K24+J24+I24+H24+G24) -> 293 | W24: =SUM(G24:U24) -> 293
A25: الجلسات التأهيلية خارج الوحدة | B25: جلسات إرشاد للأشخاص أنفسهم | C25: المستهدف الشهري | U25: 0 | V25: =SUM(U25+T25+S25+R25+Q25+P25+O25+N25+M25+L25+K25+J25+I25+H25+G25) -> 0
C26: الفعلي شهريًا | U26: 0 | V26: =SUM(U26+T26+S26+R26+Q26+P26+O26+N26+M26+L26+K26+J26+I26+H26+G26) -> 0
B27: جلسات إرشاد لأسر أ.ذ.إ | C27: المستهدف الشهري | U27: 0 | V27: =SUM(U27+T27+S27+R27+Q27+P27+O27+N27+M27+L27+K27+J27+I27+H27+G27) -> 0
C28: الفعلي شهريًا | U28: 0 | V28: =SUM(U28+T28+S28+R28+Q28+P28+O28+N28+M28+L28+K28+J28+I28+H28+G28) -> 0
B29: جلسات تأهيلية للأطفال / البالغين | C29: المستهدف الشهري | H29: 100 | N29: 150 | P29: 150 | U29: 0 | V29: =SUM(U29+T29+S29+R29+Q29+P29+O29+N29+M29+L29+K29+J29+I29+H29+G29) -> 400
C30: الفعلي شهريًا | H30: 98 | N30: 154 | P30: 167 | U30: 0 | V30: =SUM(U30+T30+S30+R30+Q30+P30+O30+N30+M30+L30+K30+J30+I30+H30+G30) -> 419 | W30: =SUM(G30:U30) -> 419
A31: الخدمات النفسية | B31: التقييمات التشخيصية | C31: المستهدف الشهري | V31: =SUM(U31+T31+S31+R31+Q31+P31+O31+N31+M31+L31+K31+J31+I31+H31+G31) -> 0
C32: الفعلي شهريًا | V32: =SUM(U32+T32+S32+R32+Q32+P32+O32+N32+M32+L32+K32+J32+I32+H32+G32) -> 0
A33: الأنشطة المجتمعية | B33: الندوات | C33: المستهدف الشهري | V33: =SUM(U33+T33+S33+R33+Q33+P33+O33+N33+M33+L33+K33+J33+I33+H33+G33) -> 0
C34: الفعلي شهريًا | V34: =SUM(U34+T34+S34+R34+Q34+P34+O34+N34+M34+L34+K34+J34+I34+H34+G34) -> 0
B35: الجولات الحرة | C35: المستهدف الشهري | V35: =SUM(U35+T35+S35+R35+Q35+P35+O35+N35+M35+L35+K35+J35+I35+H35+G35) -> 0
C36: الفعلي شهريًا | V36: =SUM(U36+T36+S36+R36+Q36+P36+O36+N36+M36+L36+K36+J36+I36+H36+G36) -> 0
B37: الأيام الترفيهية | C37: المستهدف الشهري | V37: =SUM(U37+T37+S37+R37+Q37+P37+O37+N37+M37+L37+K37+J37+I37+H37+G37) -> 0
C38: الفعلي شهريًا | V38: =SUM(U38+T38+S38+R38+Q38+P38+O38+N38+M38+L38+K38+J38+I38+H38+G38) -> 0
B39: ورش الأسر | C39: المستهدف الشهري | V39: =SUM(U39+T39+S39+R39+Q39+P39+O39+N39+M39+L39+K39+J39+I39+H39+G39) -> 0
C40: الفعلي شهريًا | V40: =SUM(U40+T40+S40+R40+Q40+P40+O40+N40+M40+L40+K40+J40+I40+H40+G40) -> 0
...

Sheet تقرير فبراير 2023
C1: وحدات مكتب منفلوط
G2: جحدم | H2: الحواتكة | I2: بنى شقير | J2: القوصية | K2: التمساحية | L2: عرب الجهمة | M2: الدير | N2: تناغة | O2: فزارة | P2: القصير | Q2: نزلة ضاهر | R2: ديروط | S2: الحوطا الغربية | T2: دشلوط | U2: زاوية هارون | V2: تونس / سوهاج | W2: إجمالى
A3: إجمالي المستفيدين | B3: إجمالي المستفيدين بالوحدة خلال العام | G3: 120 | H3: 120 | I3: 120 | J3: 120 | K3: 120 | L3: 120 | M3: 120 | N3: 120 | O3: 120 | P3: 120 | Q3: 120 | R3: 120 | S3: 120 | T3: 120 | U3: 120 | V3: 120 | W3: =SUM(V3+U3+T3+S3+R3+Q3+P3+O3+N3+M3+L3+K3+J3+I3+H3+G3) -> 1920 | X3: 1920
B4: إجمالي المستفيدين بالوحدة شهريًا | G4: 80 | H4: 120 | I4: 81 | J4: 80 | K4: 80 | L4: 15 | M4: 120 | N4: 90 | O4: 120 | P4: 120 | Q4: 120 | R4: 120 | S4: 120 | T4: 120 | U4: 0 | V4: 120 | W4: =SUM(V4+U4+T4+S4+R4+Q4+P4+O4+N4+M4+L4+K4+J4+I4+H4+G4) -> 1506 | X4: 1506
A5: عدد الأطفال ذوى الإعاقة (الجلسات التأهيلية داخل بالبرنامج ) | B5: المخطط خلال العام | G5: 20 | H5: 30 | I5: 20 | J5: 20 | K5: 30 | L5: 30 | M5: 30 | N5: 30 | O5: 30 | P5: 30 | Q5: 30 | R5: 60 | S5: 30 | T5: 30 | U5: 0 | V5: 30 | W5: =SUM(V5+U5+T5+S5+R5+Q5+P5+O5+N5+M5+L5+K5+J5+I5+H5+G5) -> 450 | X5: 450
B6: عدد الأطفال الجدد الذين تم إضافتهم خلال الشهر | G6: 0 | H6: 24 | I6: 3 | J6: 9 | K6: 24 | L6: 4 | M6: 0 | N6: 4 | O6: 0 | P6: 14 | Q6: 5 | R6: 14 | S6: 12 | T6: 0 | U6: 0 | V6: 25 | W6: =SUM(V6+U6+T6+S6+R6+Q6+P6+O6+N6+M6+L6+K6+J6+I6+H6+G6) -> 138 | X6: 138
B7: عدد الأطفال المنقطعين عن الخدمة خلال الشهر | G7: 0 | H7: 6 | I7: 5 | J7: 1 | K7: 0 | L7: 0 | M7: 0 | N7: 2 | O7: 0 | P7: 4 | Q7: 4 | R7: 0 | S7: 0 | T7: 0 | U7: 0 | V7: 2 | W7: =SUM(V7+U7+T7+S7+R7+Q7+P7+O7+N7+M7+L7+K7+J7+I7+H7+G7) -> 24 | X7: 24
B8: عدد المستفيدين شهريا من الأطفال (ذكور ) | G8: 11 | H8: 13 | I8: 13 | J8: 10 | K8: 17 | L8: 8 | M8: 0 | N8: 24 | O8: 0 | P8: 20 | Q8: 17 | R8: 12 | S8: 20 | T8: 9 | U8: 0 | V8: 17 | W8: =SUM(V8+U8+T8+S8+R8+Q8+P8+O8+N8+M8+L8+K8+J8+I8+H8+G8) -> 191 | X8: 191
B9: عدد المستفيدين شهريا من الأطفال (اناث) | G9: 9 | H9: 11 | I9: 11 | J9: 4 | K9: 14 | L9: 7 | M9: 0 | N9: 9 | O9: 0 | P9: 10 | Q9: 8 | R9: 2 | S9: 7 | T9: 7 | U9: 0 | V9: 8 | W9: =SUM(V9+U9+T9+S9+R9+Q9+P9+O9+N9+M9+L9+K9+J9+I9+H9+G9) -> 107 | X9: 107
B10: إجمالي عدد الأطفال المنتظمين بالوحدة خلال الشهر (تحت 14 عام ) | G10: 20 | H10: 24 | I10: 24 | J10: 14 | K10: 31 | L10: 15 | M10: 0 | N10: 33 | O10: 0 | P10: 30 | Q10: 25 | R10: 14 | S10: 27 | T10: 16 | U10: 0 | V10: 23 | W10: =SUM(V10+U10+T10+S10+R10+Q10+P10+O10+N10+M10+L10+K10+J10+I10+H10+G10) -> 296 | X10: 196
A11: عدد الأشخاص/الأطفال ذوى الإعاقة (الزيارات المنزلية ) | B11: المخطط خلال العام | G11: 90 | H11: 90 | I11: 90 | J11: 60 | K11: 90 | L11: 90 | M11: 90 | N11: 90 | O11: 90 | P11: 90 | Q11: 90 | R11: 0 | S11: 90 | T11: 90 | U11: 0 | V11: 90 | W11: =SUM(V11+U11+T11+S11+R11+Q11+P11+O11+N11+M11+L11+K11+J11+I11+H11+G11) -> 1230 | X11: 1230
B12: عدد الأشخاص/الأطفال الجدد الذين تم إضافتهم خلال الشهر | G12: 60 | H12: 89 | I12: 61 | J12: 0 | K12: 0 | L12: 0 | M12: 0 | N12: 27 | O12: 0 | P12: 90 | Q12: 70 | R12: 0 | S12: 15 | T12: 0 | U12: 0 | V12: 90 | W12: =SUM(V12+U12+T12+S12+R12+Q12+P12+O12+N12+M12+L12+K12+J12+I12+H12+G12) -> 502 | X12: 502
B13: عدد الأطفال المنقطعين عن الخدمة خلال الشهر | G13: 0 | H13: 0 | I13: 2 | J13: 0 | K13: 0 | L13: 0 | M13: 0 | N13: 0 | O13: 0 | P13: 0 | Q13: 0 | R13: 0 | S13: 0 | T13: 0 | U13: 0 | V13: 0 | W13: =SUM(V13+U13+T13+S13+R13+Q13+P13+O13+N13+M13+L13+K13+J13+I13+H13+G13) -> 2 | X13: 2
B14: عدد المستفيدين شهريا من الأطفال (ذكور ) | G14: 8 | H14: 11 | I14: 20 | J14: 0 | K14: 0 | L14: 0 | M14: 0 | N14: 14 | O14: 0 | P14: 8 | Q14: 5 | R14: 0 | S14: 0 | T14: 6 | U14: 0 | V14: 42 | W14: =SUM(V14+U14+T14+S14+R14+Q14+P14+O14+N14+M14+L14+K14+J14+I14+H14+G14) -> 114 | X14: 114
B15: عدد المستفيدين شهريا من الأطفال (اناث) | G15: 8 | H15: 23 | I15: 14 | J15: 0 | K15: 0 | L15: 0 | M15: 0 | N15: 10 | O15: 0 | P15: 7 | Q15: 5 | R15: 0 | S15: 0 | T15: 11 | U15: 0 | V15: 23 | W15: =SUM(V15+U15+T15+S15+R15+Q15+P15+O15+N15+M15+L15+K15+J15+I15+H15+G15) -> 101 | X15: 101
B16: عدد المستفيدين شهريا من البالغين (ذكور ) | G16: 23 | H16: 25 | I16: 15 | J16: 0 | K16: 0 | L16: 0 | M16: 0 | N16: 37 | O16: 0 | P16: 35 | Q16: 11 | R16: 0 | S16: 0 | T16: 15 | U16: 0 | V16: 15 | W16: =SUM(V16+U16+T16+S16+R16+Q16+P16+O16+N16+M16+L16+K16+J16+I16+H16+G16) -> 176 | X16: 176
B17: عدد المستفيدين شهريا من البالغين (اناث) | G17: 21 | H17: 30 | I17: 12 | J17: 0 | K17: 0 | L17: 0 | M17: 0 | N17: 26 | O17: 0 | P17: 40 | Q17: 13 | R17: 0 | S17: 0 | T17: 15 | U17: 0 | V17: 10 | W17: =SUM(V17+U17+T17+S17+R17+Q17+P17+O17+N17+M17+L17+K17+J17+I17+H17+G17) -> 167 | X17: 167
B18: إجمالي عدد المستفيدين من خدمة الزيارات المنزلية شهريًا | G18: 52 | H18: 89 | I18: 61 | J18: 0 | K18: 0 | L18: 0 | M18: 0 | N18: 71 | O18: 0 | P18: 90 | Q18: 34 | R18: 0 | S18: 15 | T18: 47 | U18: 0 | V18: 90 | W18: =SUM(V18+U18+T18+S18+R18+Q18+P18+O18+N18+M18+L18+K18+J18+I18+H18+G18) -> 549 | X18: 549
A19: الجلسات التأهيلية (داخل الوحدة) | B19: جلسات إرشاد للأشخاص أنفسهم | C19: المستهدف الشهري | K19: 0 | U19: 0 | W19: =SUM(V19+U19+T19+S19+R19+Q19+P19+O19+N19+M19+L19+K19+J19+I19+H19+G19) -> 0 | X19: 0
C20: الفعلي شهريًا | K20: 0 | U20: 0 | W20: =SUM(V20+U20+T20+S20+R20+Q20+P20+O20+N20+M20+L20+K20+J20+I20+H20+G20) -> 0 | X20: 0
B21: جلسات إرشاد لأسر أ.ذ.إ | C21: المستهدف الشهري | K21: 0 | U21: 0 | W21: =SUM(V21+U21+T21+S21+R21+Q21+P21+O21+N21+M21+L21+K21+J21+I21+H21+G21) -> 0 | X21: 0
C22: الفعلي شهريًا | K22: 0 | U22: 0 | W22: =SUM(V22+U22+T22+S22+R22+Q22+P22+O22+N22+M22+L22+K22+J22+I22+H22+G22) -> 0 | X22: 0
B23: جلسات تأهيلية للأطفال | C23: المستهدف الشهري | G23: 100 | H23: 150 | I23: 100 | J23: 100 | K23: 150 | L23: 150 | M23: 150 | N23: 150 | O23: 150 | P23: 150 | Q23: 150 | R23: 300 | S23: 150 | T23: 150 | U23: 0 | V23: 150 | W23: =SUM(V23+U23+T23+S23+R23+Q23+P23+O23+N23+M23+L23+K23+J23+I23+H23+G23) -> 2250 | X23: 2250
C24: الفعلي شهريًا | G24: 95 | H24: 132 | I24: 106 | J24: 48 | K24: 56 | L24: 90 | M24: 0 | N24: 169 | O24: 0 | P24: 85 | Q24: 23 | R24: 59 | S24: 163 | T24: 41 | U24: 0 | V24: 170 | W24: =SUM(V24+U24+T24+S24+R24+Q24+P24+O24+N24+M24+L24+K24+J24+I24+H24+G24) -> 1237 | X24: 1237
A25: الزيارات المنزلية (خارج الوحدة) | B25: جلسات إرشاد للأشخاص أنفسهم | C25: المستهدف الشهري | U25: 0 | W25: =SUM(V25+U25+T25+S25+R25+Q25+P25+O25+N25+M25+L25+K25+J25+I25+H25+G25) -> 0 | X25: 0
C26: الفعلي شهريًا | U26: 0 | W26: =SUM(V26+U26+T26+S26+R26+Q26+P26+O26+N26+M26+L26+K26+J26+I26+H26+G26) -> 0 | X26: 0
B27: جلسات إرشاد لأسر أ.ذ.إ | C27: المستهدف الشهري | U27: 0 | W27: =SUM(V27+U27+T27+S27+R27+Q27+P27+O27+N27+M27+L27+K27+J27+I27+H27+G27) -> 0 | X27: 0
C28: الفعلي شهريًا | U28: 0 | W28: =SUM(V28+U28+T28+S28+R28+Q28+P28+O28+N28+M28+L28+K28+J28+I28+H28+G28) -> 0 | X28: 0
B29: جلسات تأهيلية للأطفال / البالغين | C29: المستهدف الشهري | G29: 120 | H29: 180 | I29: 120 | J29: 0 | K29: 180 | L29: 180 | M29: 180 | N29: 180 | O29: 180 | P29: 180 | Q29: 180 | R29: 0 | S29: 180 | T29: 180 | U29: 0 | V29: 180 | W29: =SUM(V29+U29+T29+S29+R29+Q29+P29+O29+N29+M29+L29+K29+J29+I29+H29+G29) -> 2220 | X29: 2220
C30: الفعلي شهريًا | G30: 70 | H30: 89 | I30: 104 | J30: 0 | K30: 0 | L30: 62 | M30: 0 | N30: 142 | O30: 0 | P30: 167 | Q30: 34 | R30: 0 | S30: 30 | T30: 37 | U30: 0 | V30: 180 | W30: =SUM(V30+U30+T30+S30+R30+Q30+P30+O30+N30+M30+L30+K30+J30+I30+H30+G30) -> 915 | X30: 915
A31: الخدمات النفسية | B31: التقييمات التشخيصية | C31: المستهدف الشهري | W31: =SUM(V31+U31+T31+S31+R31+Q31+P31+O31+N31+M31+L31+K31+J31+I31+H31+G31) -> 0 | X31: 0
C32: الفعلي شهريًا | W32: =SUM(V32+U32+T32+S32+R32+Q32+P32+O32+N32+M32+L32+K32+J32+I32+H32+G32) -> 0 | X32: 0
A33: الأنشطة المجتمعية | B33: الندوات | C33: المستهدف الشهري | W33: =SUM(V33+U33+T33+S33+R33+Q33+P33+O33+N33+M33+L33+K33+J33+I33+H33+G33) -> 0 | X33: 0
C34: الفعلي شهريًا | W34: =SUM(V34+U34+T34+S34+R34+Q34+P34+O34+N34+M34+L34+K34+J34+I34+H34+G34) -> 0 | X34: 0
B35: الجولات الحرة | C35: المستهدف الشهري | W35: =SUM(V35+U35+T35+S35+R35+Q35+P35+O35+N35+M35+L35+K35+J35+I35+H35+G35) -> 0 | X35: 0
C36: الفعلي شهريًا | W36: =SUM(V36+U36+T36+S36+R36+Q36+P36+O36+N36+M36+L36+K36+J36+I36+H36+G36) -> 0 | X36: 0
B37: الأيام الترفيهية | C37: المستهدف الشهري | W37: =SUM(V37+U37+T37+S37+R37+Q37+P37+O37+N37+M37+L37+K37+J37+I37+H37+G37) -> 0 | X37: 0
C38: الفعلي شهريًا | N38: 1 | W38: =SUM(V38+U38+T38+S38+R38+Q38+P38+O38+N38+M38+L38+K38+J38+I38+H38+G38) -> 1 | X38: 1
B39: ورش الأسر | C39: المستهدف الشهري | W39: =SUM(V39+U39+T39+S39+R39+Q39+P39+O39+N39+M39+L39+K39+J39+I39+H39+G39) -> 0 | X39: 0
C40: الفعلي شهريًا | W40: =SUM(V40+U40+T40+S40+R40+Q40+P40+O40+N40+M40+L40+K40+J40+I40+H40+G40) -> 0 | X40: 0
...

Sheet تقرير مارس 2023
C1: وحدات مكتب منفلوط | V1: مكتب سوهاج | Z1: مكتب بنى سويف
G2: جحدم | H2: الحواتكة | I2: بنى شقير | J2: القوصية | K2: التمساحية | L2: عرب الجهمة | M2: الدير | N2: تناغة | O2: فزارة | P2: القصير | Q2: نزلة ضاهر | R2: ديروط | S2: الحوطا الغربية | T2: دشلوط | U2: زاوية هارون | V2: تونس | W2: المنشأه | X2: العسيرات | Y2: كوم بدار | Z2: فزارة | AA2: ببا | AB2: إجمالى
A3: إجمالي المستفيدين | B3: إجمالي المستفيدين بالوحدة خلال العام | G3: 120 | H3: 120 | I3: 120 | J3: 120 | K3: 120 | L3: 120 | M3: 120 | N3: 120 | O3: 120 | P3: 120 | Q3: 120 | R3: 120 | S3: 120 | T3: 120 | U3: 0 | V3: 120 | W3: 120 | X3: 120 | Y3: 120 | Z3: 120 | AA3: 120 | AB3: =SUM(AA3+Z3+Y3+X3+W3+V3+U3+T3+S3+R3+Q3+P3+O3+N3+M3+L3+K3+J3+I3+H3+G3) -> 2400
B4: إجمالي المستفيدين بالوحدة شهريًا | G4: 80 | H4: 120 | I4: 81 | J4: 80 | K4: 80 | L4: 15 | M4: 120 | N4: 90 | O4: 120 | P4: 120 | Q4: 120 | R4: 120 | S4: 120 | T4: 120 | U4: 0 | V4: 120 | W4: 120 | X4: 120 | Y4: 120 | Z4: 120 | AA4: 120 | AB4: =SUM(AA4+Z4+Y4+X4+W4+V4+U4+T4+S4+R4+Q4+P4+O4+N4+M4+L4+K4+J4+I4+H4+G4) -> 2106
A5: عدد الأطفال ذوى الإعاقة (الجلسات التأهيلية داخل بالبرنامج ) | B5: المخطط خلال العام | G5: 50 | H5: 50 | I5: 50 | J5: 75 | K5: 50 | L5: 50 | M5: 50 | N5: 50 | O5: 50 | P5: 50 | Q5: 50 | R5: 75 | S5: 50 | T5: 50 | U5: 0 | V5: 50 | W5: 50 | X5: 50 | Y5: 50 | Z5: 50 | AA5: 50 | AB5: =SUM(AA5+Z5+Y5+X5+W5+V5+U5+T5+S5+R5+Q5+P5+O5+N5+M5+L5+K5+J5+I5+H5+G5) -> 1050
B6: عدد الأطفال الجدد الذين تم إضافتهم خلال الشهر | G6: 0 | H6: 6 | I6: 3 | J6: 2 | K6: 0 | L6: 3 | M6: 30 | N6: 0 | O6: 0 | Q6: 0 | R6: 12 | S6: 0 | U6: 0 | V6: 3 | AA6: 8 | AB6: =SUM(AA6+Z6+Y6+X6+W6+V6+U6+T6+S6+R6+Q6+P6+O6+N6+M6+L6+K6+J6+I6+H6+G6) -> 67
B7: عدد الأطفال المنقطعين عن الخدمة خلال الشهر | G7: 10 | H7: 0 | I7: 2 | J7: 2 | K7: 12 | L7: 1 | M7: 0 | N7: 3 | O7: 0 | P7: 0 | Q7: 8 | R7: 0 | S7: 0 | T7: 1 | U7: 0 | V7: 2 | W7: 7 | Z7: 3 | AA7: 9 | AB7: =SUM(AA7+Z7+Y7+X7+W7+V7+U7+T7+S7+R7+Q7+P7+O7+N7+M7+L7+K7+J7+I7+H7+G7) -> 60
B8: عدد المستفيدين شهريا من الأطفال (ذكور ) | G8: 2 | H8: 18 | I8: 10 | J8: 11 | K8: 15 | L8: 9 | M8: 26 | N8: 21 | O8: 19 | P8: 20 | Q8: 11 | R8: 14 | S8: 20 | T8: 7 | U8: 0 | V8: 14 | W8: 13 | X8: 8 | Y8: 6 | Z8: 12 | AA8: 12 | AB8: =SUM(AA8+Z8+Y8+X8+W8+V8+U8+T8+S8+R8+Q8+P8+O8+N8+M8+L8+K8+J8+I8+H8+G8) -> 268
B9: عدد المستفيدين شهريا من الأطفال (اناث) | G9: 8 | H9: 12 | I9: 12 | J9: 3 | K9: 5 | L9: 9 | M9: 4 | N9: 9 | O9: 7 | P9: 10 | Q9: 6 | R9: 12 | S9: 7 | T9: 8 | U9: 0 | V9: 9 | W9: 5 | X9: 8 | Y9: 5 | Z9: 12 | AA9: 16 | AB9: =SUM(AA9+Z9+Y9+X9+W9+V9+U9+T9+S9+R9+Q9+P9+O9+N9+M9+L9+K9+J9+I9+H9+G9) -> 167
B10: إجمالي عدد الأطفال المنتظمين بالوحدة خلال الشهر (تحت 14 عام ) | G10: =SUM(G8+G9) -> 10 | H10: =SUM(H8+H9) -> 30 | I10: =SUM(I8+I9) -> 22 | J10: =SUM(J8+J9) -> 14 | K10: =SUM(K8+K9) -> 20 | L10: =SUM(L8+L9) -> 18 | M10: =SUM(M8+M9) -> 30 | N10: =SUM(N8+N9) -> 30 | ... AA10: =SUM(AA8+AA9) -> 28 | AB10: =SUM(AA10+Z10+Y10+X10+W10+V10+U10+T10+S10+R10+Q10+P10+O10+N10+M10+L10+K10+J10+I10+H10+G10) -> 435
A11: عدد الأشخاص الذين تم رصدهم | B11: عدد الأشخاص الذين تم رصدهم بالكامل | N11: 271 | Q11: 337 | AB11: =SUM(AA11+Z11+Y11+X11+W11+V11+U11+T11+S11+R11+Q11+P11+O11+N11+M11+L11+K11+J11+I11+H11+G11) -> 608
B12: عدد الأشخاص الذين تم رصدهم خلال الشهر | N12: 7 | Q12: 93 | AB12: =SUM(AA12+Z12+Y12+X12+W12+V12+U12+T12+S12+R12+Q12+P12+O12+N12+M12+L12+K12+J12+I12+H12+G12) -> 100
A13: عدد الأشخاص/الأطفال ذوى الإعاقة (الزيارات المنزلية ) | B13: المخطط خلال العام | N13: 0 | Q13: 0 | AB13: =SUM(AA13+Z13+Y13+X13+W13+V13+U13+T13+S13+R13+Q13+P13+O13+N13+M13+L13+K13+J13+I13+H13+G13) -> 0
B14: عدد الأشخاص/الأطفال الجدد الذين تم إضافتهم خلال الشهر | G14: 60 | I14: 0 | J14: 0 | K14: 0 | L14: 0 | M14: 0 | N14: 0 | O14: 0 | P14: 0 | Q14: 11 | R14: 0 | T14: 28 | U14: 0 | W14: 0 | AA14: 1 | AB14: =SUM(AA14+Z14+Y14+X14+W14+V14+U14+T14+S14+R14+Q14+P14+O14+N14+M14+L14+K14+J14+I14+H14+G14) -> 100
B15: عدد الأطفال المنقطعين عن الخدمة خلال الشهر | G15: 0 | I15: 1 | J15: 0 | K15: 0 | L15: 0 | M15: 0 | N15: 0 | O15: 0 | P15: 0 | Q15: 0 | R15: 0 | T15: 0 | U15: 0 | W15: 5 | X15: 0 | Y15: 0 | Z15: 9 | AA15: 6 | AB15: =SUM(AA15+Z15+Y15+X15+W15+V15+U15+T15+S15+R15+Q15+P15+O15+N15+M15+L15+K15+J15+I15+H15+G15) -> 21
B16: عدد المستفيدين شهريا من الأطفال (ذكور ) | G16: 7 | H16: 11 | I16: 20 | J16: 0 | K16: 2 | L16: 12 | M16: 4 | N16: 14 | O16: 4 | P16: 8 | Q16: 16 | R16: 0 | T16: 19 | U16: 0 | V16: 42 | W16: 9 | X16: 0 | Y16: 0 | Z16: 15 | AA16: 4 | AB16: =SUM(AA16+Z16+Y16+X16+W16+V16+U16+T16+S16+R16+Q16+P16+O16+N16+M16+L16+K16+J16+I16+H16+G16) -> 187
B17: عدد المستفيدين شهريا من الأطفال (اناث) | G17: 7 | H17: 23 | I17: 13 | J17: 0 | K17: 4 | L17: 7 | M17: 6 | N17: 10 | O17: 2 | P17: 7 | Q17: 13 | R17: 0 | T17: 17 | U17: 0 | V17: 23 | W17: 13 | X17: 0 | Y17: 0 | Z17: 11 | AA17: 13 | AB17: =SUM(AA17+Z17+Y17+X17+W17+V17+U17+T17+S17+R17+Q17+P17+O17+N17+M17+L17+K17+J17+I17+H17+G17) -> 169
B18: عدد المستفيدين شهريا من البالغين (ذكور ) | G18: 5 | H18: 26 | I18: 15 | J18: 0 | K18: 13 | L18: 20 | M18: 38 | N18: 37 | O18: 3 | P18: 35 | Q18: 10 | R18: 0 | T18: 17 | U18: 0 | V18: 15 | W18: 25 | X18: 0 | Y18: 14 | Z18: 17 | AA18: 8 | AB18: =SUM(AA18+Z18+Y18+X18+W18+V18+U18+T18+S18+R18+Q18+P18+O18+N18+M18+L18+K18+J18+I18+H18+G18) -> 298
B19: عدد المستفيدين شهريا من البالغين (اناث) | G19: 12 | H19: 30 | I19: 12 | J19: 0 | K19: 20 | L19: 15 | M19: 42 | N19: 26 | O19: 6 | P19: 40 | Q19: 6 | R19: 0 | T19: 22 | U19: 0 | V19: 10 | W19: 22 | X19: 0 | Y19: 13 | Z19: 14 | AA19: 9 | AB19: =SUM(AA19+Z19+Y19+X19+W19+V19+U19+T19+S19+R19+Q19+P19+O19+N19+M19+L19+K19+J19+I19+H19+G19) -> 299
B20: إجمالي عدد المستفيدين من خدمة الزيارات المنزلية شهريًا | G20: 33 | H20: =SUM(H16+H17+H18+H19) -> 90 | I20: 60 | J20: =SUM(J16+J17+J18+J19) -> 0 | K20: =SUM(K16+K17+K18+K19) -> 39 | L20: =SUM(L16+L17+L18+L19) -> 54 | M20: =SUM(M16+M17+M18+M19) -> 90 | N20: =SUM(N16+N17+N18+N19) -> 87 | O20: 15 | P20: =SUM(P16+P17+P18+P19) -> 90 | Q20: =SUM(Q16+Q17+Q18+Q19) -> 45 | R20: =SUM(R16+R17+R18+R19) -> 0 | S20: =SUM(S16+S17+S18+S19) -> 0 | T20: =SUM(T16+T17+T18+T19) -> 75 | U20: =SUM(U16+U17+U18+U19) -> 0 | V20: =SUM(V16+V17+V18+V19) -> 90 | W20: =SUM(W16+W17+W18+W19) -> 69 | ... AA20: =SUM(AA16+AA17+AA18+AA19) -> 34 | AB20: =SUM(AA20+Z20+Y20+X20+W20+V20+U20+T20+S20+R20+Q20+P20+O20+N20+M20+L20+K20+J20+I20+H20+G20) -> 955
A21: جلسات تأهيل داخل الوحدة | B21: جلسات إرشاد لأسر أ.ذ.إ | C21: المستهدف الشهري | K21: 0 | U21: 0 | AB21: =SUM(AA21+Z21+Y21+X21+W21+V21+U21+T21+S21+R21+Q21+P21+O21+N21+M21+L21+K21+J21+I21+H21+G21) -> 0
C22: الفعلي شهريًا | K22: 0 | N22: 2 | U22: 0 | V22: 5 | AB22: =SUM(AA22+Z22+Y22+X22+W22+V22+U22+T22+S22+R22+Q22+P22+O22+N22+M22+L22+K22+J22+I22+H22+G22) -> 7
B23: جلسات تأهيلية للأطفال | C23: المستهدف الشهري | G23: 100 | H23: 150 | I23: 100 | J23: 100 | K23: 150 | L23: 150 | M23: 150 | N23: 150 | O23: 150 | P23: 150 | Q23: 150 | R23: 300 | S23: 150 | T23: 150 | U23: 0 | V23: 150 | W23: 150 | X23: 150 | Y23: 150 | Z23: 150 | AA23: 150 | AB23: =SUM(AA23+Z23+Y23+X23+W23+V23+U23+T23+S23+R23+Q23+P23+O23+N23+M23+L23+K23+J23+I23+H23+G23) -> 3000
C24: الفعلي شهريًا | G24: 68 | H24: 93 | I24: 90 | J24: 52 | K24: 58 | L24: 100 | M24: 134 | N24: 135 | O24: 68 | P24: 85 | Q24: 97 | R24: 77 | S24: 120 | T24: 103 | U24: 0 | V24: 168 | W24: 44 | X24: 87 | Y24: 70 | Z24: 99 | AA24: 120 | AB24: =SUM(AA24+Z24+Y24+X24+W24+V24+U24+T24+S24+R24+Q24+P24+O24+N24+M24+L24+K24+J24+I24+H24+G24) -> 1868
A25: الزيارات المنزلية (خارج الوحدة) | B25: جلسات إرشاد للأشخاص أنفسهم | C25: المستهدف الشهري | U25: 0 | AB25: =SUM(AA25+Z25+Y25+X25+W25+V25+U25+T25+S25+R25+Q25+P25+O25+N25+M25+L25+K25+J25+I25+H25+G25) -> 0
C26: الفعلي شهريًا | G26: 20 | H26: 112 | I26: 40 | N26: 5 | P26: 135 | Q26: 25 | U26: 0 | AB26: =SUM(AA26+Z26+Y26+X26+W26+V26+U26+T26+S26+R26+Q26+P26+O26+N26+M26+L26+K26+J26+I26+H26+G26) -> 337
B27: جلسات إرشاد لأسر أ.ذ.إ | C27: المستهدف الشهري | AB27: =SUM(AA27+Z27+Y27+X27+W27+V27+U27+T27+S27+R27+Q27+P27+O27+N27+M27+L27+K27+J27+I27+H27+G27) -> 0
C28: الفعلي شهريًا | H28: 57 | L28: 90 | N28: 3 | O28: 10 | P28: 15 | Q28: 17 | AB28: =SUM(AA28+Z28+Y28+X28+W28+V28+U28+T28+S28+R28+Q28+P28+O28+N28+M28+L28+K28+J28+I28+H28+G28) -> 192
B29: جلسات تأهيلية للأطفال / البالغين (تنمية قدرات/ تنمية المهارات اللغوية/ تنمية المهارات الحركية/ تنمية المهارات الأكاديمية) | C29: المستهدف الشهري | AB29: =SUM(AA29+Z29+Y29+X29+W29+V29+U29+T29+S29+R29+Q29+P29+O29+N29+M29+L29+K29+J29+I29+H29+G29) -> 0
C30: الفعلي شهريًا | G30: 20 | H30: 28 | M30: 160 | N30: 174 | O30: 6 | P30: 25 | Q30: 25 | AB30: =SUM(AA30+Z30+Y30+X30+W30+V30+U30+T30+S30+R30+Q30+P30+O30+N30+M30+L30+K30+J30+I30+H30+G30) -> 438
B31: زيارات تستهدف خدمات إجتماعية | C31: المستهدف الشهري | N31: 0 | Q31: 0 | U31: 0 | AB31: =SUM(AA31+Z31+Y31+X31+W31+V31+U31+T31+S31+R31+Q31+P31+O31+N31+M31+L31+K31+J31+I31+H31+G31) -> 0
C32: الفعلي شهريًا | G32: 15 | I32: 55 | N32: 0 | Q32: 15 | U32: 0 | AB32: =SUM(AA32+Z32+Y32+X32+W32+V32+U32+T32+S32+R32+Q32+P32+O32+N32+M32+L32+K32+J32+I32+H32+G32) -> 85
B33: إجمالي عدد الزيارات المنفذة | C33: المستهدف الشهري | G33: 120 | H33: 180 | I33: 120 | J33: 0 | K33: 180 | L33: 180 | M33: 180 | N33: 180 | O33: 180 | P33: 180 | Q33: 180 | R33: 0 | S33: 180 | T33: 180 | U33: 0 | V33: 180 | W33: 180 | X33: 180 | Y33: 180 | Z33: 180 | AA33: 180 | AB33: =SUM(AA33+Z33+Y33+X33+W33+V33+U33+T33+S33+R33+Q33+P33+O33+N33+M33+L33+K33+J33+I33+H33+G33) -> 3120
C34: الفعلي شهريًا | G34: =SUM(G26+G28+G30+G32) -> 55 | H34: =SUM(H26+H28+H30+H32) -> 197 | I34: =SUM(I26+I28+I30+I32) -> 95 | J34: =SUM(J26+J28+J30+J32) -> 0 | K34: 37 | L34: 90 | M34: =SUM(M26+M28+M30+M32) -> 160 | N34: =SUM(N26+N28+N30+N32) -> 182 | O34: =SUM(O26+O28+O30+O32) -> 16 | P34: =SUM(P26+P28+P30+P32) -> 175 | Q34: =SUM(Q26+Q28+Q30+Q32) -> 82 | R34: =SUM(R26+R28+R30+R32) -> 0 | S34: 90 | T34: 78 | U34: =SUM(U26+U28+U30+U32) -> 0 | V34: 180 | W34: 140 | X34: 0 | Y34: 54 | Z34: 130 | AA34: 124 | AB34: =SUM(AA34+Z34+Y34+X34+W34+V34+U34+T34+S34+R34+Q34+P34+O34+N34+M34+L34+K34+J34+I34+H34+G34) -> 1885
A35: الخدمات النفسية | B35: التقييمات التشخيصية | C35: المستهدف الشهري | AB35: =SUM(AA35+Z35+Y35+X35+W35+V35+U35+T35+S35+R35+Q35+P35+O35+N35+M35+L35+K35+J35+I35+H35+G35) -> 0
C36: الفعلي شهريًا | Q36: 11 | AB36: =SUM(AA36+Z36+Y36+X36+W36+V36+U36+T36+S36+R36+Q36+P36+O36+N36+M36+L36+K36+J36+I36+H36+G36) -> 11
A37: الأنشطة المجتمعية | B37: الندوات | C37: المستهدف الشهري | I37: 1 | N37: 1 | Q37: 1 | T37: 1 | AB37: =SUM(AA37+Z37+Y37+X37+W37+V37+U37+T37+S37+R37+Q37+P37+O37+N37+M37+L37+K37+J37+I37+H37+G37) -> 4
C38: الفعلي شهريًا | I38: 1 | N38: 1 | Q38: 1 | T38: 1 | AB38: =SUM(AA38+Z38+Y38+X38+W38+V38+U38+T38+S38+R38+Q38+P38+O38+N38+M38+L38+K38+J38+I38+H38+G38) -> 4
B39: الجولات الحرة | C39: المستهدف الشهري | M39: 1 | AB39: =SUM(AA39+Z39+Y39+X39+W39+V39+U39+T39+S39+R39+Q39+P39+O39+N39+M39+L39+K39+J39+I39+H39+G39) -> 1
C40: الفعلي شهريًا | M40: 1 | AB40: =SUM(AA40+Z40+Y40+X40+W40+V40+U40+T40+S40+R40+Q40+P40+O40+N40+M40+L40+K40+J40+I40+H40+G40) -> 1
...

Sheet تقرير أبريل 2023
C1: وحدات مكتب منفلوط | V1: مكتب سوهاج | AA1: مكتب بنى سويف
G2: جحدم | H2: الحواتكة | I2: بنى شقير | J2: القوصية | K2: التمساحية | L2: عرب الجهمة | M2: الدير | N2: تناغة | O2: فزارة | P2: القصير | Q2: نزلة ضاهر | R2: ديروط | S2: الحوطا الغربية | T2: دشلوط | U2: زاوية هارون | V2: تونس | W2: المنشأه | X2: العسيرات | Y2: كوم بدار | Z2: فزارة | AA2: النويرة | AB2: ببا | AC2: إجمالى
A3: إجمالي المستفيدين | B3: إجمالي المستفيدين بالوحدة خلال العام | G3: 120 | H3: 120 | I3: 120 | J3: 120 | K3: 120 | L3: 120 | M3: 120 | N3: 120 | O3: 120 | P3: 120 | Q3: 120 | R3: 120 | S3: 120 | T3: 120 | U3: 0 | V3: 120 | W3: 120 | X3: 120 | Y3: 120 | Z3: 120 | AA3: 120 | AB3: 120 | AC3: =SUM(AB3+AA3+Z3+Y3+X3+W3+V3+U3+T3+S3+R3+Q3+P3+O3+N3+M3+L3+K3+J3+I3+H3+G3) -> 2520
B4: إجمالي المستفيدين بالوحدة شهريًا | G4: 80 | H4: 120 | I4: 81 | J4: 80 | K4: 80 | L4: 120 | M4: 120 | N4: 90 | O4: 120 | P4: 120 | Q4: 120 | R4: 120 | S4: 120 | T4: 120 | U4: 0 | V4: 120 | W4: 120 | X4: 120 | Y4: 120 | Z4: 120 | AA4: 120 | AB4: 120 | AC4: =SUM(AB4+AA4+Z4+Y4+X4+W4+V4+U4+T4+S4+R4+Q4+P4+O4+N4+M4+L4+K4+J4+I4+H4+G4) -> 2331
A5: عدد الأطفال ذوى الإعاقة (الجلسات التأهيلية داخل بالبرنامج ) | B5: المخطط خلال العام | G5: 50 | H5: 50 | I5: 50 | J5: 75 | K5: 50 | L5: 50 | M5: 50 | N5: 50 | O5: 50 | P5: 50 | Q5: 50 | R5: 75 | S5: 50 | T5: 50 | U5: 0 | V5: 50 | W5: 50 | X5: 50 | Y5: 50 | Z5: 50 | AA5: 50 | AB5: 50 | AC5: =SUM(AB5+AA5+Z5+Y5+X5+W5+V5+U5+T5+S5+R5+Q5+P5+O5+N5+M5+L5+K5+J5+I5+H5+G5) -> 1100
B6: عدد الأطفال الجدد الذين تم إضافتهم خلال الشهر | G6: 11 | H6: 6 | I6: 1 | J6: 4 | K6: 0 | L6: 3 | M6: 30 | N6: 0 | O6: 2 | Q6: 6 | R6: 3 | S6: 1 | U6: 0 | V6: 1 | W6: 1 | Z6: 3 | AA6: 0 | AB6: 3 | AC6: =SUM(AB6+AA6+Z6+Y6+X6+W6+V6+U6+T6+S6+R6+Q6+P6+O6+N6+M6+L6+K6+J6+I6+H6+G6) -> 75
B7: عدد الأطفال المنقطعين عن الخدمة خلال الشهر | G7: 0 | H7: 0 | I7: 2 | J7: 0 | K7: 5 | L7: 1 | M7: 2 | N7: 17 | O7: 4 | P7: 0 | Q7: 8 | R7: 6 | S7: 3 | T7: 0 | U7: 0 | V7: 1 | W7: 6 | Z7: 0 | AA7: 0 | AB7: 0 | AC7: =SUM(AB7+AA7+Z7+Y7+X7+W7+V7+U7+T7+S7+R7+Q7+P7+O7+N7+M7+L7+K7+J7+I7+H7+G7) -> 55
B8: عدد المستفيدين شهريا من الأطفال (ذكور ) | G8: 10 | H8: 18 | I8: 10 | J8: 14 | K8: 11 | L8: 9 | M8: 25 | N8: 11 | O8: 17 | P8: 20 | Q8: 14 | R8: 18 | S8: 21 | T8: 7 | U8: 0 | V8: 16 | W8: 9 | X8: 8 | Y8: 18 | Z8: 14 | AA8: 9 | AB8: 15 | AC8: =SUM(AB8+AA8+Z8+Y8+X8+W8+V8+U8+T8+S8+R8+Q8+P8+O8+N8+M8+L8+K8+J8+I8+H8+G8) -> 294
B9: عدد المستفيدين شهريا من الأطفال (اناث) | G9: 11 | H9: 12 | I9: 11 | J9: 4 | K9: 4 | L9: 9 | M9: 3 | N9: 2 | O9: 7 | P9: 10 | Q9: 9 | R9: 12 | S9: 7 | T9: 8 | U9: 0 | V9: 8 | W9: 3 | X9: 8 | Y9: 9 | Z9: 13 | AA9: 8 | AB9: 16 | AC9: =SUM(AB9+AA9+Z9+Y9+X9+W9+V9+U9+T9+S9+R9+Q9+P9+O9+N9+M9+L9+K9+J9+I9+H9+G9) -> 174
B10: إجمالي عدد الأطفال المنتظمين بالوحدة خلال الشهر (تحت 14 عام ) | G10: =SUM(G8+G9) -> 21 | H10: =SUM(H8+H9) -> 30 | I10: =SUM(I8+I9) -> 21 | J10: =SUM(J8+J9) -> 18 | K10: =SUM(K8+K9) -> 15 | L10: =SUM(L8+L9) -> 18 | M10: =SUM(M8+M9) -> 28 | N10: =SUM(N8+N9) -> 13 | ... AB10: =SUM(AB8+AB9) -> 31 | AC10: =SUM(AB10+AA10+Z10+Y10+X10+W10+V10+U10+T10+S10+R10+Q10+P10+O10+N10+M10+L10+K10+J10+I10+H10+G10) -> 468
A11: عدد الأشخاص الذين تم رصدهم | B11: عدد الأشخاص الذين تم رصدهم بالكامل | N11: 276 | Q11: 337 | AC11: =SUM(AB11+AA11+Z11+Y11+X11+W11+V11+U11+T11+S11+R11+Q11+P11+O11+N11+M11+L11+K11+J11+I11+H11+G11) -> 613
B12: عدد الأشخاص الذين تم رصدهم خلال الشهر | N12: 6 | Q12: 93 | AC12: =SUM(AB12+AA12+Z12+Y12+X12+W12+V12+U12+T12+S12+R12+Q12+P12+O12+N12+M12+L12+K12+J12+I12+H12+G12) -> 99
A13: عدد الأشخاص/الأطفال ذوى الإعاقة (الزيارات المنزلية ) | B13: المخطط خلال العام | N13: 0 | Q13: 0 | AC13: =SUM(AB13+AA13+Z13+Y13+X13+W13+V13+U13+T13+S13+R13+Q13+P13+O13+N13+M13+L13+K13+J13+I13+H13+G13) -> 0
B14: عدد الأشخاص/الأطفال الجدد الذين تم إضافتهم خلال الشهر | G14: 60 | I14: 1 | J14: 0 | K14: 0 | L14: 0 | M14: 0 | N14: 0 | O14: 0 | P14: 0 | Q14: 11 | R14: 0 | T14: 28 | U14: 0 | W14: 0 | AC14: =SUM(AB14+AA14+Z14+Y14+X14+W14+V14+U14+T14+S14+R14+Q14+P14+O14+N14+M14+L14+K14+J14+I14+H14+G14) -> 100
B15: عدد الأطفال المنقطعين عن الخدمة خلال الشهر | G15: 0 | I15: 1 | J15: 0 | K15: 2 | L15: 0 | M15: 0 | N15: 0 | O15: 0 | P15: 0 | Q15: 0 | R15: 0 | T15: 0 | U15: 0 | W15: 5 | X15: 0 | Y15: 0 | Z15: 9 | AB15: 0 | AC15: =SUM(AB15+AA15+Z15+Y15+X15+W15+V15+U15+T15+S15+R15+Q15+P15+O15+N15+M15+L15+K15+J15+I15+H15+G15) -> 17
B16: عدد المستفيدين شهريا من الأطفال (ذكور ) | G16: 8 | H16: 11 | I16: 19 | J16: 0 | K16: 0 | L16: 12 | M16: 4 | N16: 14 | O16: 11 | P16: 8 | Q16: 17 | R16: 0 | T16: 19 | U16: 0 | V16: 42 | W16: 9 | X16: 17 | Y16: 25 | Z16: 18 | AB16: 4 | AC16: =SUM(AB16+AA16+Z16+Y16+X16+W16+V16+U16+T16+S16+R16+Q16+P16+O16+N16+M16+L16+K16+J16+I16+H16+G16) -> 238
B17: عدد المستفيدين شهريا من الأطفال (اناث) | G17: 12 | H17: 23 | I17: 14 | J17: 0 | K17: 4 | L17: 7 | M17: 6 | N17: 10 | O17: 7 | P17: 7 | Q17: 14 | R17: 0 | T17: 17 | U17: 0 | V17: 23 | W17: 13 | X17: 5 | Y17: 12 | Z17: 11 | AB17: 13 | AC17: =SUM(AB17+AA17+Z17+Y17+X17+W17+V17+U17+T17+S17+R17+Q17+P17+O17+N17+M17+L17+K17+J17+I17+H17+G17) -> 198
B18: عدد المستفيدين شهريا من البالغين (ذكور ) | G18: 11 | H18: 26 | I18: 15 | J18: 0 | K18: 25 | L18: 20 | M18: 38 | N18: 37 | O18: 16 | P18: 35 | Q18: 14 | R18: 0 | S18: 23 | T18: 17 | U18: 0 | V18: 15 | W18: 42 | X18: 4 | Y18: 24 | Z18: 17 | AB18: 8 | AC18: =SUM(AB18+AA18+Z18+Y18+X18+W18+V18+U18+T18+S18+R18+Q18+P18+O18+N18+M18+L18+K18+J18+I18+H18+G18) -> 387
B19: عدد المستفيدين شهريا من البالغين (اناث) | G19: 33 | H19: 30 | I19: 12 | J19: 0 | K19: 20 | L19: 15 | M19: 42 | N19: 26 | O19: 24 | P19: 40 | Q19: 15 | R19: 0 | S19: 19 | T19: 22 | U19: 0 | V19: 10 | W19: 26 | X19: 28 | Y19: 21 | Z19: 18 | AB19: 9 | AC19: =SUM(AB19+AA19+Z19+Y19+X19+W19+V19+U19+T19+S19+R19+Q19+P19+O19+N19+M19+L19+K19+J19+I19+H19+G19) -> 410
B20: إجمالي عدد المستفيدين من خدمة الزيارات المنزلية شهريًا | G20: =SUM(G16:G19) -> 64 | H20: =SUM(H16:H19) -> 90 | I20: =SUM(I16:I19) -> 60 | J20: =SUM(J16:J19) -> 0 | K20: =SUM(K16:K19) -> 49 | L20: =SUM(L16:L19) -> 54 | M20: =SUM(M16:M19) -> 90 | N20: =SUM(N16:N19) -> 87 | ... Y20: =SUM(Y16:Y19) -> 82 | Z20: =SUM(Z16+Z17+Z18+Z19) -> 64 | AA20: =SUM(AA16:AA19) -> 0 | AB20: =SUM(AB16+AB17+AB18+AB19) -> 34 | AC20: =SUM(AB20+AA20+Z20+Y20+X20+W20+V20+U20+T20+S20+R20+Q20+P20+O20+N20+M20+L20+K20+J20+I20+H20+G20) -> 1233
A21: جلسات تأهيل داخل الوحدة | B21: جلسات إرشاد لأسر أ.ذ.إ | C21: المستهدف الشهري | K21: 0 | U21: 0 | AC21: =SUM(AB21+AA21+Z21+Y21+X21+W21+V21+U21+T21+S21+R21+Q21+P21+O21+N21+M21+L21+K21+J21+I21+H21+G21) -> 0
C22: الفعلي شهريًا | K22: 0 | N22: 2 | U22: 0 | V22: 5 | AC22: =SUM(AB22+AA22+Z22+Y22+X22+W22+V22+U22+T22+S22+R22+Q22+P22+O22+N22+M22+L22+K22+J22+I22+H22+G22) -> 7
B23: جلسات تأهيلية للأطفال | C23: المستهدف الشهري | G23: 100 | H23: 150 | I23: 100 | J23: 100 | K23: 150 | L23: 150 | M23: 150 | N23: 150 | O23: 150 | P23: 150 | Q23: 150 | R23: 300 | S23: 150 | T23: 150 | U23: 0 | V23: 150 | W23: 150 | X23: 150 | Y23: 150 | Z23: 150 | AA23: 150 | AB23: 150 | AC23: =SUM(AB23+AA23+Z23+Y23+X23+W23+V23+U23+T23+S23+R23+Q23+P23+O23+N23+M23+L23+K23+J23+I23+H23+G23) -> 3150
C24: الفعلي شهريًا | G24: 70 | H24: 90 | I24: 73 | J24: 36 | K24: 28 | L24: 50 | M24: 92 | N24: 57 | O24: 90 | P24: 95 | Q24: 63 | R24: 53 | S24: 75 | T24: 69 | U24: 0 | V24: 148 | W24: 30 | X24: 70 | Y24: 144 | Z24: 100 | AA24: 75 | AB24: 119 | AC24: =SUM(AB24+AA24+Z24+Y24+X24+W24+V24+U24+T24+S24+R24+Q24+P24+O24+N24+M24+L24+K24+J24+I24+H24+G24) -> 1627
A25: الزيارات المنزلية (خارج الوحدة) | B25: جلسات إرشاد للأشخاص أنفسهم | C25: المستهدف الشهري | U25: 0 | AC25: =SUM(AB25+AA25+Z25+Y25+X25+W25+V25+U25+T25+S25+R25+Q25+P25+O25+N25+M25+L25+K25+J25+I25+H25+G25) -> 0
C26: الفعلي شهريًا | G26: 20 | H26: 112 | I26: 40 | P26: 135 | U26: 0 | AC26: =SUM(AB26+AA26+Z26+Y26+X26+W26+V26+U26+T26+S26+R26+Q26+P26+O26+N26+M26+L26+K26+J26+I26+H26+G26) -> 307
B27: جلسات إرشاد لأسر أ.ذ.إ | C27: المستهدف الشهري | AC27: =SUM(AB27+AA27+Z27+Y27+X27+W27+V27+U27+T27+S27+R27+Q27+P27+O27+N27+M27+L27+K27+J27+I27+H27+G27) -> 0
